Workbook

Sheet КАТАЛОГ
A1: КАТАЛОГ
A2: Раздел | B2: Описание | C2: Код
A3: 1 | B3: Разработка КД, секции и элементы IP 55 | C3: 8000
A4: 2 | B4: Разработка КД, секции IP 68 | C4: 8100
A5: 3 | B5: Разработка КД аксессуаров и комплектующих | C5: 8200

Sheet БАЗА
A1: Код | B1: IP | C1: Артикул элемента | D1: Разработка параметрических моделей для обработки ИИ | E1: Измеритель | F1: Норма выработки за час, шт. | G1: Трудоем-кость, чел/час (часы на разработку)
A2: 1 | B2: 2 | C2: 4 | D2: 5 | E2: 6 | F2: 7 | G2: 8
D3: 1. Разработка КД, секции и элементы IP 55
A4: 8001 | B4: 55 | C4: AC | D4: Разработка КД центральной питающей секции | E4: шт. | F4: =1/G4 -> 0.22321429 | G4: 4.48
A5: 8002 | B5: 55 | C5: AC | D5: Изменение КД центральной питающей секции | E5: шт. | F5: =1/G5 -> 0.44642857 | G5: 2.24
A6: 8003 | B6: 55 | C6: ADP | D6: Разработка КД переходного элемента ШП | E6: шт. | F6: =1/G6 -> 0.25510204 | G6: 3.92
A7: 8004 | B7: 55 | C7: ADP-S | D7: Изменение КД переходного элемента ШП | E7: шт. | F7: =1/G7 -> 0.51020408 | G7: 1.96
A8: 8005 | B8: 55 | C8: ATCD | D8: Разработка КД терминальной секции с гор. углом | E8: шт. | F8: =1/G8 -> 0.12755102 | G8: 7.84
A9: 8006 | B9: 55 | C9: ATCD | D9: Изменение КД терминальной секции с гор. углом | E9: шт. | F9: =1/G9 -> 0.35714286 | G9: 2.8
A10: 8007 | B10: 55 | C10: ATCP | D10: Разработка КД терминальной секции с вертикальным углом | E10: шт. | F10: =1/G10 -> 0.11160714 | G10: 8.96
A11: 8008 | B11: 55 | C11: ATCP-S | D11: Изменение КД терминальной секции свертикальным углом | E11: шт. | F11: =1/G11 -> 0.29761905 | G11: 3.36
A12: 8009 | B12: 55 | C12: ATSC | D12: Разработка КД терминальной секции | E12: шт. | F12: =1/G12 -> 0.14880952 | G12: 6.72
A13: 8010 | B13: 55 | C13: ATSC-S | D13: Изменение КД терминальной секции | E13: шт. | F13: =1/G13 -> 0.29761905 | G13: 3.36
A14: 8011 | B14: 55 | C14: ATT | D14: Разработка КД терминальной трансформаторной секции | E14: шт. | F14: =1/G14 -> 0.14880952 | G14: 6.72
A15: 8012 | B15: 55 | C15: ATT-S | D15: Изменение КД терминальной трансформаторной секции | E15: шт. | F15: =1/G15 -> 0.44642857 | G15: 2.24
... A70: 8065 | B70: 55 | C70: ZP-S | D70: Изменение ПМ Z-образной вертикальной секции | E70: шт. | F70: =1/G70 -> 0.17857143 | G70: 5.6
D71: 2. Разработка КД, секции IP 68
A72: 8100 | B72: 68 | C72: ADP | D72: Разработка переходного элемента ШП | E72: шт. | F72: =1/G72 -> 0.22321429 | G72: 4.48
A73: 8101 | B73: 68 | C73: ADP-S | D73: Изменение переходного элемента ШП | E73: шт. | F73: =1/G73 -> 0.44642857 | G73: 2.24
A74: 8102 | B74: 68 | C74: ATSC | D74: Разработка КД терминальной секции | E74: шт. | F74: =1/G74 -> 0.074404762 | G74: 13.44
A75: 8103 | B75: 68 | C75: ATSC | D75: Изменение КД терминальной секции | E75: шт. | F75: =1/G75 -> 0.17857143 | G75: 5.6
A76: 8103.1 | B76: 68 | C76: ATCP | D76: Разработка КД терминальной секции с вертикальным углом | E76: шт. | F76: =1/G76 -> 0.071428571 | G76: 14
A77: 8103.2 | B77: 68 | C77: ATCP-S | D77: Изменение КД терминальной секции свертикальным углом | E77: шт. | F77: =1/G77 -> 0.14285714 | G77: 7
A78: 8104 | B78: 68 | C78: CD | D78: Разработка Эталона ПМ горизонтального угла ЛШП | E78: шт. | F78: =1/G78 -> 0.074404762 | G78: 13.44
A79: 8105 | B79: 68 | C79: CD-I | D79: Изменение номинала горизонтального угла | E79: шт. | F79: =1/G79 -> 0.1984127 | G79: 5.04
A80: 8106 | B80: 68 | C80: CD-S | D80: Изменение длины горизонтального угла | E80: шт. | F80: =1/G80 -> 0.29761905 | G80: 3.36
A81: 8107 | B81: 68 | C81: CP | D81: Разработка Эталона ПМ вертикального угла | E81: шт. | F81: =1/G81 -> 0.06377551 | G81: 15.68
A82: 8108 | B82: 68 | C82: CP-I | D82: Изменение номинала вертикального угла | E82: шт. | F82: =1/G82 -> 0.13736264 | G82: 7.28
A83: 8109 | B83: 68 | C83: CP-S | D83: Изменение длины вертикального угла | E83: шт. | F83: =1/G83 -> 0.17857143 | G83: 5.6
... A94: 8120 | B94: 68 | C94: ZP-S | D94: Изменение длины Z-образной вертикальной секции | E94: шт. | F94: =1/G94 -> 0.17857143 | G94: 5.6
D95: 3. Разработка КД аксессуаров и комплектующих
A96: 8200 | B96: - | C96: - | D96: Изменение КД Автомата без ручки управления | E96: шт. | F96: =1/G96 -> 1.7857143 | G96: 0.56
A97: 8201 | B97: - | C97: - | D97: Изменение КД Автомата с ручкой управления | E97: шт. | F97: =1/G97 -> 0.35714286 | G97: 2.8
A98: 8202 | B98: - | C98: FB | D98: Разработка КД Комплекта для огнестойкой проходки ШП | E98: шт. | F98: =1/G98 -> 0.44642857 | G98: 2.24
A99: 8203 | B99: - | C99: FB | D99: Изменение КД Комплекта для огнестойкой проходки ШП | E99: шт. | F99: =1/G99 -> 0.89285714 | G99: 1.12
A100: 8204 | B100: - | C100: - | D100: Изменение КД окна отбора мощности | E100: шт. | F100: =1/G100 -> 0.29761905 | G100: 3.36
A101: 8205 | B101: - | C101: EC | D101: Изменение ПМ Концевой заглушки | E101: шт. | F101: =1/G101 -> 0.89285714 | G101: 1.12
A102: 8206 | B102: - | C102: - | D102: Разработка (изменение) Прижимной решётки для торц. загл. | E102: шт. | F102: =1/G102 -> 0.89285714 | G102: 1.12
A103: 8207 | B103: - | C103: - | D103: Разработка (изменение) Торцевой заглушки | E103: шт. | F103: =1/G103 -> 1.7857143 | G103: 0.56
A104: 8208 | B104: - | C104: - | D104: Разработка КД Автомата без ручки управления | E104: шт. | F104: =1/G104 -> 1.7857143 | G104: 0.56
...

Sheet IP 55
A1: Код | B1: IP | C1: Артикул элемента | D1: Разработка КД | E1: Измеритель | F1: Норма выработки за час, шт. | G1: Трудоем-кость, чел/час (часы на разработку)
A2: 8001 | B2: =VLOOKUP(A2,БАЗА!A:G,2,0) -> 55 | C2: =VLOOKUP(A2,БАЗА!A:G,3,0) -> AC | D2: =VLOOKUP(A2,БАЗА!A:G,4,0) -> Разработка КД центральной питающей секции | E2: =VLOOKUP(A2,БАЗА!A:G,5,0) -> шт. | F2: =1/G2 -> 0.22321429 | G2: =VLOOKUP(A2,БАЗА!A:G,7,0) -> 4.48
A3: 8002 | B3: =VLOOKUP(A3,БАЗА!A:G,2,0) -> 55 | C3: =VLOOKUP(A3,БАЗА!A:G,3,0) -> AC | D3: =VLOOKUP(A3,БАЗА!A:G,4,0) -> Изменение КД центральной питающей секции | E3: =VLOOKUP(A3,БАЗА!A:G,5,0) -> шт. | F3: =1/G3 -> 0.44642857 | G3: =VLOOKUP(A3,БАЗА!A:G,7,0) -> 2.24
A4: 8003 | B4: =VLOOKUP(A4,БАЗА!A:G,2,0) -> 55 | C4: =VLOOKUP(A4,БАЗА!A:G,3,0) -> ADP | D4: =VLOOKUP(A4,БАЗА!A:G,4,0) -> Разработка КД переходного элемента ШП | E4: =VLOOKUP(A4,БАЗА!A:G,5,0) -> шт. | F4: =1/G4 -> 0.25510204 | G4: =VLOOKUP(A4,БАЗА!A:G,7,0) -> 3.92
A5: 8004 | B5: =VLOOKUP(A5,БАЗА!A:G,2,0) -> 55 | C5: =VLOOKUP(A5,БАЗА!A:G,3,0) -> ADP-S | D5: =VLOOKUP(A5,БАЗА!A:G,4,0) -> Изменение КД переходного элемента ШП | E5: =VLOOKUP(A5,БАЗА!A:G,5,0) -> шт. | F5: =1/G5 -> 0.51020408 | G5: =VLOOKUP(A5,БАЗА!A:G,7,0) -> 1.96
A6: 8005 | B6: =VLOOKUP(A6,БАЗА!A:G,2,0) -> 55 | C6: =VLOOKUP(A6,БАЗА!A:G,3,0) -> ATCD | D6: =VLOOKUP(A6,БАЗА!A:G,4,0) -> Разработка КД терминальной секции с гор. углом | E6: =VLOOKUP(A6,БАЗА!A:G,5,0) -> шт. | F6: =1/G6 -> 0.12755102 | G6: =VLOOKUP(A6,БАЗА!A:G,7,0) -> 7.84
A7: 8006 | B7: =VLOOKUP(A7,БАЗА!A:G,2,0) -> 55 | C7: =VLOOKUP(A7,БАЗА!A:G,3,0) -> ATCD | D7: =VLOOKUP(A7,БАЗА!A:G,4,0) -> Изменение КД терминальной секции с гор. углом | E7: =VLOOKUP(A7,БАЗА!A:G,5,0) -> шт. | F7: =1/G7 -> 0.35714286 | G7: =VLOOKUP(A7,БАЗА!A:G,7,0) -> 2.8
A8: 8007 | B8: =VLOOKUP(A8,БАЗА!A:G,2,0) -> 55 | C8: =VLOOKUP(A8,БАЗА!A:G,3,0) -> ATCP | D8: =VLOOKUP(A8,БАЗА!A:G,4,0) -> Разработка КД терминальной секции с вертикальным углом | E8: =VLOOKUP(A8,БАЗА!A:G,5,0) -> шт. | F8: =1/G8 -> 0.11160714 | G8: =VLOOKUP(A8,БАЗА!A:G,7,0) -> 8.96
A9: 8008 | B9: =VLOOKUP(A9,БАЗА!A:G,2,0) -> 55 | C9: =VLOOKUP(A9,БАЗА!A:G,3,0) -> ATCP-S | D9: =VLOOKUP(A9,БАЗА!A:G,4,0) -> Изменение КД терминальной секции свертикальным углом | E9: =VLOOKUP(A9,БАЗА!A:G,5,0) -> шт. | F9: =1/G9 -> 0.29761905 | G9: =VLOOKUP(A9,БАЗА!A:G,7,0) -> 3.36
A10: 8009 | B10: =VLOOKUP(A10,БАЗА!A:G,2,0) -> 55 | C10: =VLOOKUP(A10,БАЗА!A:G,3,0) -> ATSC | D10: =VLOOKUP(A10,БАЗА!A:G,4,0) -> Разработка КД терминальной секции | E10: =VLOOKUP(A10,БАЗА!A:G,5,0) -> шт. | F10: =1/G10 -> 0.14880952 | G10: =VLOOKUP(A10,БАЗА!A:G,7,0) -> 6.72
A11: 8010 | B11: =VLOOKUP(A11,БАЗА!A:G,2,0) -> 55 | C11: =VLOOKUP(A11,БАЗА!A:G,3,0) -> ATSC-S | D11: =VLOOKUP(A11,БАЗА!A:G,4,0) -> Изменение КД терминальной секции | E11: =VLOOKUP(A11,БАЗА!A:G,5,0) -> шт. | F11: =1/G11 -> 0.29761905 | G11: =VLOOKUP(A11,БАЗА!A:G,7,0) -> 3.36
A12: 8011 | B12: =VLOOKUP(A12,БАЗА!A:G,2,0) -> 55 | C12: =VLOOKUP(A12,БАЗА!A:G,3,0) -> ATT | D12: =VLOOKUP(A12,БАЗА!A:G,4,0) -> Разработка КД терминальной трансформаторной секции | E12: =VLOOKUP(A12,БАЗА!A:G,5,0) -> шт. | F12: =1/G12 -> 0.14880952 | G12: =VLOOKUP(A12,БАЗА!A:G,7,0) -> 6.72
A13: 8012 | B13: =VLOOKUP(A13,БАЗА!A:G,2,0) -> 55 | C13: =VLOOKUP(A13,БАЗА!A:G,3,0) -> ATT-S | D13: =VLOOKUP(A13,БАЗА!A:G,4,0) -> Изменение КД терминальной трансформаторной секции | E13: =VLOOKUP(A13,БАЗА!A:G,5,0) -> шт. | F13: =1/G13 -> 0.44642857 | G13: =VLOOKUP(A13,БАЗА!A:G,7,0) -> 2.24
... A69: 8066 | B69: =VLOOKUP(A69,БАЗА!A:G,2,0) -> #N/A | C69: =VLOOKUP(A69,БАЗА!A:G,3,0) -> #N/A | D69: =VLOOKUP(A69,БАЗА!A:G,4,0) -> #N/A | E69: =VLOOKUP(A69,БАЗА!A:G,5,0) -> #N/A | F69: =1/G69 -> #N/A | G69: =VLOOKUP(A69,БАЗА!A:G,7,0) -> #N/A

Sheet IP 68
A1: Код | B1: IP | C1: Артикул элемента | D1: Разработка КД | E1: Измеритель | F1: Норма выработки за час, шт. | G1: Трудоем-кость, чел/час (часы на разработку)
A2: 8100 | B2: =VLOOKUP(A2,БАЗА!A:G,2,0) -> 68 | C2: =VLOOKUP(A2,БАЗА!A:G,3,0) -> ADP | D2: =VLOOKUP(A2,БАЗА!A:G,4,0) -> Разработка переходного элемента ШП | E2: =VLOOKUP(A2,БАЗА!A:G,5,0) -> шт. | F2: =1/G2 -> 0.22321429 | G2: =VLOOKUP(A2,БАЗА!A:G,7,0) -> 4.48
A3: 8101 | B3: =VLOOKUP(A3,БАЗА!A:G,2,0) -> 68 | C3: =VLOOKUP(A3,БАЗА!A:G,3,0) -> ADP-S | D3: =VLOOKUP(A3,БАЗА!A:G,4,0) -> Изменение переходного элемента ШП | E3: =VLOOKUP(A3,БАЗА!A:G,5,0) -> шт. | F3: =1/G3 -> 0.44642857 | G3: =VLOOKUP(A3,БАЗА!A:G,7,0) -> 2.24
A4: 8102 | B4: =VLOOKUP(A4,БАЗА!A:G,2,0) -> 68 | C4: =VLOOKUP(A4,БАЗА!A:G,3,0) -> ATSC | D4: =VLOOKUP(A4,БАЗА!A:G,4,0) -> Разработка КД терминальной секции | E4: =VLOOKUP(A4,БАЗА!A:G,5,0) -> шт. | F4: =1/G4 -> 0.074404762 | G4: =VLOOKUP(A4,БАЗА!A:G,7,0) -> 13.44
A5: 8103 | B5: =VLOOKUP(A5,БАЗА!A:G,2,0) -> 68 | C5: =VLOOKUP(A5,БАЗА!A:G,3,0) -> ATSC | D5: =VLOOKUP(A5,БАЗА!A:G,4,0) -> Изменение КД терминальной секции | E5: =VLOOKUP(A5,БАЗА!A:G,5,0) -> шт. | F5: =1/G5 -> 0.17857143 | G5: =VLOOKUP(A5,БАЗА!A:G,7,0) -> 5.6
A6: 8103.1 | B6: =VLOOKUP(A6,БАЗА!A:G,2,0) -> 68 | C6: =VLOOKUP(A6,БАЗА!A:G,3,0) -> ATCP | D6: =VLOOKUP(A6,БАЗА!A:G,4,0) -> Разработка КД терминальной секции с вертикальным углом | E6: =VLOOKUP(A6,БАЗА!A:G,5,0) -> шт. | F6: =1/G6 -> 0.071428571 | G6: =VLOOKUP(A6,БАЗА!A:G,7,0) -> 14
A7: 8103.2 | B7: =VLOOKUP(A7,БАЗА!A:G,2,0) -> 68 | C7: =VLOOKUP(A7,БАЗА!A:G,3,0) -> ATCP-S | D7: =VLOOKUP(A7,БАЗА!A:G,4,0) -> Изменение КД терминальной секции свертикальным углом | E7: =VLOOKUP(A7,БАЗА!A:G,5,0) -> шт. | F7: =1/G7 -> 0.14285714 | G7: =VLOOKUP(A7,БАЗА!A:G,7,0) -> 7
A8: 8104 | B8: =VLOOKUP(A8,БАЗА!A:G,2,0) -> 68 | C8: =VLOOKUP(A8,БАЗА!A:G,3,0) -> CD | D8: =VLOOKUP(A8,БАЗА!A:G,4,0) -> Разработка Эталона ПМ горизонтального угла ЛШП | E8: =VLOOKUP(A8,БАЗА!A:G,5,0) -> шт. | F8: =1/G8 -> 0.074404762 | G8: =VLOOKUP(A8,БАЗА!A:G,7,0) -> 13.44
A9: 8105 | B9: =VLOOKUP(A9,БАЗА!A:G,2,0) -> 68 | C9: =VLOOKUP(A9,БАЗА!A:G,3,0) -> CD-I | D9: =VLOOKUP(A9,БАЗА!A:G,4,0) -> Изменение номинала горизонтального угла | E9: =VLOOKUP(A9,БАЗА!A:G,5,0) -> шт. | F9: =1/G9 -> 0.1984127 | G9: =VLOOKUP(A9,БАЗА!A:G,7,0) -> 5.04
A10: 8106 | B10: =VLOOKUP(A10,БАЗА!A:G,2,0) -> 68 | C10: =VLOOKUP(A10,БАЗА!A:G,3,0) -> CD-S | D10: =VLOOKUP(A10,БАЗА!A:G,4,0) -> Изменение длины горизонтального угла | E10: =VLOOKUP(A10,БАЗА!A:G,5,0) -> шт. | F10: =1/G10 -> 0.29761905 | G10: =VLOOKUP(A10,БАЗА!A:G,7,0) -> 3.36
A11: 8107 | B11: =VLOOKUP(A11,БАЗА!A:G,2,0) -> 68 | C11: =VLOOKUP(A11,БАЗА!A:G,3,0) -> CP | D11: =VLOOKUP(A11,БАЗА!A:G,4,0) -> Разработка Эталона ПМ вертикального угла | E11: =VLOOKUP(A11,БАЗА!A:G,5,0) -> шт. | F11: =1/G11 -> 0.06377551 | G11: =VLOOKUP(A11,БАЗА!A:G,7,0) -> 15.68
A12: 8108 | B12: =VLOOKUP(A12,БАЗА!A:G,2,0) -> 68 | C12: =VLOOKUP(A12,БАЗА!A:G,3,0) -> CP-I | D12: =VLOOKUP(A12,БАЗА!A:G,4,0) -> Изменение номинала вертикального угла | E12: =VLOOKUP(A12,БАЗА!A:G,5,0) -> шт. | F12: =1/G12 -> 0.13736264 | G12: =VLOOKUP(A12,БАЗА!A:G,7,0) -> 7.28
A13: 8109 | B13: =VLOOKUP(A13,БАЗА!A:G,2,0) -> 68 | C13: =VLOOKUP(A13,БАЗА!A:G,3,0) -> CP-S | D13: =VLOOKUP(A13,БАЗА!A:G,4,0) -> Изменение длины вертикального угла | E13: =VLOOKUP(A13,БАЗА!A:G,5,0) -> шт. | F13: =1/G13 -> 0.17857143 | G13: =VLOOKUP(A13,БАЗА!A:G,7,0) -> 5.6
... A25: 8121 | B25: =VLOOKUP(A25,БАЗА!A:G,2,0) -> #N/A | C25: =VLOOKUP(A25,БАЗА!A:G,3,0) -> #N/A | D25: =VLOOKUP(A25,БАЗА!A:G,4,0) -> #N/A | E25: =VLOOKUP(A25,БАЗА!A:G,5,0) -> #N/A | F25: =1/G25 -> #N/A | G25: =VLOOKUP(A25,БАЗА!A:G,7,0) -> #N/A

Sheet Аксес. и компл.
A1: Код | B1: IP | C1: Артикул элемента | D1: Разработка КД | E1: Измеритель | F1: Норма выработки за час, шт. | G1: Трудоем-кость, чел/час (часы на разработку)
A2: 8200 | B2: =VLOOKUP(A2,БАЗА!A:G,2,0) -> - | C2: =VLOOKUP(A2,БАЗА!A:G,3,0) -> - | D2: =VLOOKUP(A2,БАЗА!A:G,4,0) -> Изменение КД Автомата без ручки управления | E2: =VLOOKUP(A2,БАЗА!A:G,5,0) -> шт. | F2: =1/G2 -> 1.7857143 | G2: =VLOOKUP(A2,БАЗА!A:G,7,0) -> 0.56
A3: 8201 | B3: =VLOOKUP(A3,БАЗА!A:G,2,0) -> - | C3: =VLOOKUP(A3,БАЗА!A:G,3,0) -> - | D3: =VLOOKUP(A3,БАЗА!A:G,4,0) -> Изменение КД Автомата с ручкой управления | E3: =VLOOKUP(A3,БАЗА!A:G,5,0) -> шт. | F3: =1/G3 -> 0.35714286 | G3: =VLOOKUP(A3,БАЗА!A:G,7,0) -> 2.8
A4: 8202 | B4: =VLOOKUP(A4,БАЗА!A:G,2,0) -> - | C4: =VLOOKUP(A4,БАЗА!A:G,3,0) -> FB | D4: =VLOOKUP(A4,БАЗА!A:G,4,0) -> Разработка КД Комплекта для огнестойкой проходки ШП | E4: =VLOOKUP(A4,БАЗА!A:G,5,0) -> шт. | F4: =1/G4 -> 0.44642857 | G4: =VLOOKUP(A4,БАЗА!A:G,7,0) -> 2.24
A5: 8203 | B5: =VLOOKUP(A5,БАЗА!A:G,2,0) -> - | C5: =VLOOKUP(A5,БАЗА!A:G,3,0) -> FB | D5: =VLOOKUP(A5,БАЗА!A:G,4,0) -> Изменение КД Комплекта для огнестойкой проходки ШП | E5: =VLOOKUP(A5,БАЗА!A:G,5,0) -> шт. | F5: =1/G5 -> 0.89285714 | G5: =VLOOKUP(A5,БАЗА!A:G,7,0) -> 1.12
A6: 8204 | B6: =VLOOKUP(A6,БАЗА!A:G,2,0) -> - | C6: =VLOOKUP(A6,БАЗА!A:G,3,0) -> - | D6: =VLOOKUP(A6,БАЗА!A:G,4,0) -> Изменение КД окна отбора мощности | E6: =VLOOKUP(A6,БАЗА!A:G,5,0) -> шт. | F6: =1/G6 -> 0.29761905 | G6: =VLOOKUP(A6,БАЗА!A:G,7,0) -> 3.36
A7: 8205 | B7: =VLOOKUP(A7,БАЗА!A:G,2,0) -> - | C7: =VLOOKUP(A7,БАЗА!A:G,3,0) -> EC | D7: =VLOOKUP(A7,БАЗА!A:G,4,0) -> Изменение ПМ Концевой заглушки | E7: =VLOOKUP(A7,БАЗА!A:G,5,0) -> шт. | F7: =1/G7 -> 0.89285714 | G7: =VLOOKUP(A7,БАЗА!A:G,7,0) -> 1.12
A8: 8206 | B8: =VLOOKUP(A8,БАЗА!A:G,2,0) -> - | C8: =VLOOKUP(A8,БАЗА!A:G,3,0) -> - | D8: =VLOOKUP(A8,БАЗА!A:G,4,0) -> Разработка (изменение) Прижимной решётки для торц. загл. | E8: =VLOOKUP(A8,БАЗА!A:G,5,0) -> шт. | F8: =1/G8 -> 0.89285714 | G8: =VLOOKUP(A8,БАЗА!A:G,7,0) -> 1.12
A9: 8207 | B9: =VLOOKUP(A9,БАЗА!A:G,2,0) -> - | C9: =VLOOKUP(A9,БАЗА!A:G,3,0) -> - | D9: =VLOOKUP(A9,БАЗА!A:G,4,0) -> Разработка (изменение) Торцевой заглушки | E9: =VLOOKUP(A9,БАЗА!A:G,5,0) -> шт. | F9: =1/G9 -> 1.7857143 | G9: =VLOOKUP(A9,БАЗА!A:G,7,0) -> 0.56
A10: 8208 | B10: =VLOOKUP(A10,БАЗА!A:G,2,0) -> - | C10: =VLOOKUP(A10,БАЗА!A:G,3,0) -> - | D10: =VLOOKUP(A10,БАЗА!A:G,4,0) -> Разработка КД Автомата без ручки управления | E10: =VLOOKUP(A10,БАЗА!A:G,5,0) -> шт. | F10: =1/G10 -> 1.7857143 | G10: =VLOOKUP(A10,БАЗА!A:G,7,0) -> 0.56
A11: 8209 | B11: =VLOOKUP(A11,БАЗА!A:G,2,0) -> - | C11: =VLOOKUP(A11,БАЗА!A:G,3,0) -> - | D11: =VLOOKUP(A11,БАЗА!A:G,4,0) -> Разработка КД Автомата с ручкой управления | E11: =VLOOKUP(A11,БАЗА!A:G,5,0) -> шт. | F11: =1/G11 -> 0.44642857 | G11: =VLOOKUP(A11,БАЗА!A:G,7,0) -> 2.24
A12: 8210 | B12: =VLOOKUP(A12,БАЗА!A:G,2,0) -> - | C12: =VLOOKUP(A12,БАЗА!A:G,3,0) -> - | D12: =VLOOKUP(A12,БАЗА!A:G,4,0) -> Разработка КД Изолятора | E12: =VLOOKUP(A12,БАЗА!A:G,5,0) -> шт. | F12: =1/G12 -> 0.89285714 | G12: =VLOOKUP(A12,БАЗА!A:G,7,0) -> 1.12
A13: 8211 | B13: =VLOOKUP(A13,БАЗА!A:G,2,0) -> - | C13: =VLOOKUP(A13,БАЗА!A:G,3,0) -> PTC | D13: =VLOOKUP(A13,БАЗА!A:G,4,0) -> Разработка КД Луженой переходной медной пластины | E13: =VLOOKUP(A13,БАЗА!A:G,5,0) -> шт. | F13: =1/G13 -> 0.89285714 | G13: =VLOOKUP(A13,БАЗА!A:G,7,0) -> 1.12
... A19: 8217 | B19: =VLOOKUP(A19,БАЗА!A:G,2,0) -> #N/A | C19: =VLOOKUP(A19,БАЗА!A:G,3,0) -> #N/A | D19: =VLOOKUP(A19,БАЗА!A:G,4,0) -> #N/A | E19: =VLOOKUP(A19,БАЗА!A:G,5,0) -> #N/A | F19: =1/G19 -> #N/A | G19: =VLOOKUP(A19,БАЗА!A:G,7,0) -> #N/A
