Workbook

Sheet БАЗА
A1: БАЗА!A491
B2: Дата обновления ведомости: | G2: 46235
A3: КОД | B3: Описание | C3: Измеритель | D3: Кол-во исп. | E3: Норма в час (н. в см./11) | F3: Трудоем-кость, чел/час | G3: Норма выраб.за смену, шт | H3: Штучно-калькуляционное время, мин | I3: К=1 +Tпз+Том+Тлн | J3: Трудоем-кость, чел/час | K3: Норма выраб.за смену, шт | L3: Оперативное время в смене, мин.: | M3: Доступное время (11 ч), мин.
B4: Повременные работы и хоз.работы
A5: 00001 | B5: Сбор картона по цеху, транспортировка к прессу, сортировка, удаление посторонних материалов, прессование куба, перемещение в место хранения. | C5: куб | D5: 1 | E5: =G5/11 -> 1.6363636 | F5: =J5 -> 0.61111111 | G5: =K5 -> 18 | H5: 33.333333 | I5: =M5/L5 -> 1.1 | J5: =11/K5 -> 0.61111111 | K5: =M5/(H5*I5) -> 18 | L5: 600 | M5: 660
A6: 00002 | B6: Повременные работы | C6: час | D6: 1 | E6: =G6/11 -> 1 | F6: =11/G6 -> 1 | G6: =L6/H6 -> 11 | H6: 54.545455 | I6: =M6/L6 -> 1.1 | J6: =11/K6 -> 1 | K6: =M6/(H6*I6) -> 11 | L6: 600 | M6: 660
A7: 00003 | B7: Повременные работы. Заготовительные операции. | C7: час | D7: 1 | E7: =G7/11 -> 1 | F7: =11/G7 -> 1 | G7: =L7/H7 -> 11 | H7: 54.545455 | I7: =M7/L7 -> 1.1 | J7: =11/K7 -> 1 | K7: =M7/(H7*I7) -> 11 | L7: 600 | M7: 660
A8: 00004 | B8: Повременные работы. Сборка | C8: час | D8: 1 | E8: =G8/11 -> 1 | F8: =11/G8 -> 1 | G8: =L8/H8 -> 11 | H8: 54.545455 | I8: =M8/L8 -> 1.1 | J8: =11/K8 -> 1 | K8: =M8/(H8*I8) -> 11 | L8: 600 | M8: 660
A9: 00005 | B9: Повременные работы. Сварка. | C9: час | D9: 1 | E9: =G9/11 -> 1 | F9: =11/G9 -> 1 | G9: =L9/H9 -> 11 | H9: 54.545455 | I9: =M9/L9 -> 1.1 | J9: =11/K9 -> 1 | K9: =M9/(H9*I9) -> 11 | L9: 600 | M9: 660
A10: 00006 | B10: Повременные работы. Работа на лазере | C10: час | D10: 1 | E10: =G10/11 -> 1 | F10: =11/G10 -> 1 | G10: =L10/H10 -> 11 | H10: 54.545455 | I10: =M10/L10 -> 1.1 | J10: =11/K10 -> 1 | K10: =M10/(H10*I10) -> 11 | L10: 600 | M10: 660
A11: 00007 | B11: Повременные работы. Заливка ЛШП, Гаскетинг | C11: час | D11: 1 | E11: =G11/11 -> 1 | F11: =11/G11 -> 1 | G11: =L11/H11 -> 11 | H11: 54.545455 | I11: =M11/L11 -> 1.1 | J11: =11/K11 -> 1 | K11: =M11/(H11*I11) -> 11 | L11: 600 | M11: 660
A12: 00008 | B12: Повременные работы по упаковке и укладке. | C12: час | D12: 1 | E12: =G12/11 -> 1 | F12: =11/G12 -> 1 | G12: =L12/H12 -> 11 | H12: 54.545455 | I12: =M12/L12 -> 1.1 | J12: =11/K12 -> 1 | K12: =M12/(H12*I12) -> 11 | L12: 600 | M12: 660
A13: 00009 | B13: Простой, ожидание не по вине работника | C13: час | D13: 1 | E13: =G13/11 -> 1 | F13: =11/G13 -> 1 | G13: =L13/H13 -> 11 | H13: 54.545455 | I13: =M13/L13 -> 1.1 | J13: =11/K13 -> 1 | K13: =M13/(H13*I13) -> 11 | L13: 600 | M13: 660
A14: 00010 | B14: Переделка брака по вине сотрудников других отделов/участков | C14: час | D14: 1 | E14: =G14/11 -> 1 | F14: =11/G14 -> 1 | G14: =L14/H14 -> 11 | H14: 54.545455 | I14: =M14/L14 -> 1.1 | J14: =11/K14 -> 1 | K14: =M14/(H14*I14) -> 11 | L14: 600 | M14: 660
A15: 00011 | B15: Простой, ожидание по вине КО | C15: час | D15: 1 | E15: =G15/11 -> 1 | F15: =11/G15 -> 1 | G15: =L15/H15 -> 11 | H15: 54.545455 | I15: 1.1 | J15: 1 | K15: 11 | L15: 600 | M15: 660
A16: 00012 | B16: Простой, ожидание по вине склада | C16: час | D16: 1 | E16: =G16/11 -> 1 | F16: =11/G16 -> 1 | G16: =L16/H16 -> 11 | H16: 54.545455 | I16: 1.1 | J16: 1 | K16: 11 | L16: 600 | M16: 660
A17: 00013 | B17: Простой, ожидание ввиду отсутствия комплектующих | C17: час | D17: 1 | E17: =G17/11 -> 1 | F17: =11/G17 -> 1 | G17: =L17/H17 -> 11 | H17: 54.545455 | I17: 1.1 | J17: 1 | K17: 11 | L17: 600 | M17: 660
A18: 00014 | B18: Простой, по причине механических поломок, ремонта. | C18: час | D18: 1 | E18: =G18/11 -> 1 | F18: =11/G18 -> 1 | G18: =L18/H18 -> 11 | H18: 54.545455 | I18: =M18/L18 -> 1.1 | J18: =11/K18 -> 1 | K18: =M18/(H18*I18) -> 11 | L18: 600 | M18: 660
A19: 00030 | B19: Y. T. FE-IP55. Торцовка на пиле прямых секций после сборки. | C19: час | D19: 1 | E19: =G19/11 -> 1 | F19: =11/G19 -> 1 | G19: =L19/H19 -> 11 | H19: 54.545455 | I19: =M19/L19 -> 1.1 | J19: =11/K19 -> 1 | K19: =M19/(H19*I19) -> 11 | L19: 600 | M19: 660
A20: 00031 | B20: Y. T. FE-IP68. Торцовка на пиле прямых литых секций после сборки. | C20: час | D20: 1 | E20: =G20/11 -> 1 | F20: =11/G20 -> 1 | G20: =L20/H20 -> 11 | H20: 54.545455 | I20: =M20/L20 -> 1.1 | J20: =11/K20 -> 1 | K20: =M20/(H20*I20) -> 11 | L20: 600 | M20: 660
A21: 00032 | B21: Y.T. CZ-IP55. Торцовка на пиле непрямых секций после сборки. | C21: час | D21: 1 | E21: =G21/11 -> 1 | F21: =11/G21 -> 1 | G21: =L21/H21 -> 11 | H21: 54.545455 | I21: =M21/L21 -> 1.1 | J21: =11/K21 -> 1 | K21: =M21/(H21*I21) -> 11 | L21: 600 | M21: 660
A22: 00033 | B22: Y.T. CZ-IP68. Торцовка на пиле непрямых литых секций после сборки. | C22: час | D22: 1 | E22: =G22/11 -> 1 | F22: =11/G22 -> 1 | G22: =L22/H22 -> 11 | H22: 54.545455 | I22: =M22/L22 -> 1.1 | J22: =11/K22 -> 1 | K22: =M22/(H22*I22) -> 11 | L22: 600 | M22: 660
A23: 00190 | B23: ИЗ.ПОВР. ATT. Изолирование нестандартных (по форме, габаритам, гибам, флажкам) шин для трансформаторных секций | C23: час | D23: 1 | E23: =G23/11 -> 1 | F23: =11/G23 -> 1 | G23: =L23/H23 -> 11 | H23: 54.545455 | I23: =M23/L23 -> 1.1 | J23: =11/K23 -> 1 | K23: =M23/(H23*I23) -> 11 | L23: 600 | M23: 660
A24: 00220 | B24: ПС. ПОВР. АTT. Полная сборка крупногабаритных нестандартных трансформаторных секций (IP 55-68) | C24: час | D24: 1 | E24: =G24/11 -> 1 | F24: =11/G24 -> 1 | G24: =L24/H24 -> 11 | H24: 54.545455 | I24: =M24/L24 -> 1.1 | J24: =11/K24 -> 1 | K24: =M24/(H24*I24) -> 11 | L24: 600 | M24: 660
A25: 00270 | B25: СБ.ЯОМ. ЭКСП. Экспериментальная, нетиповая сборка яом, работа с тех.специалистами, разработка схем расключения. | C25: час | D25: 1 | E25: =G25/11 -> 0.86580087 | F25: =J25 -> 1.155 | G25: =K25 -> 9.5238095 | H25: 63 | I25: =M25/L25 -> 1.1 | J25: =11/K25 -> 1.155 | K25: =M25/(H25*I25) -> 9.5238095 | L25: 600 | M25: 660
A26: 00300 | B26: Работа на экструдере, цех №1 | C26: час | D26: 1 | E26: 1 | F26: 1 | G26: 11 | H26: 54.545455
A27: 00500 | B27: НАП. Шин для АТТ. Напыление крупногабаритных (сложной формы) шин из листа (более 200 мм) | C27: час | D27: 1 | E27: =G27/11 -> 1 | F27: =11/G27 -> 1 | G27: =L27/H27 -> 11 | H27: 54.545455 | I27: =M27/L27 -> 1.1 | J27: =11/K27 -> 1 | K27: =M27/(H27*I27) -> 11 | L27: 600 | M27: 660
A28: 00666 | B28: КОРРЕКТИРОВКА НОРМ (применяется в случае явного несоответствия нормы времени и фактической трудоемкости, необходима для закрытия наряда и акцентирования внимания). | C28: час | D28: 1 | E28: =G28/11 -> 1 | F28: =11/G28 -> 1 | G28: =L28/H28 -> 11 | H28: 54.545455 | I28: =M28/L28 -> 1.1 | J28: =11/K28 -> 1 | K28: =M28/(H28*I28) -> 11 | L28: 600 | M28: 660
B29: Участок напыления (кту 1,2)
A30: 00501 | B30: Замена сопла на ДИМЕТ | C30: шт | D30: 1 | E30: =G30/11 -> 12.731157 | F30: =11/G30 -> 0.078547458 | G30: =L30/H30 -> 140.04272 | H30: 4.213 | I30: =M30/L30 -> 1.1186441 | J30: =11/K30 -> 0.078547458 | K30: =M30/(H30*I30) -> 140.04272 | L30: 590 | M30: 660
A31: 00505 | B31: Приготовление 5 кг (1 тарная единица) смеси для напыления (новый порошок + рекупират) в утвержденной пропорции. | C31: шт | D31: 1 | E31: =G31/11 -> 10.727273 | F31: =11/G31 -> 0.093220339 | G31: =L31/H31 -> 118 | H31: 5 | I31: =M31/L31 -> 1.1186441 | J31: =11/K31 -> 0.093220339 | K31: =M31/(H31*I31) -> 118 | L31: 590 | M31: 660
B32: Напыление шин
A33: 00510 | B33: НАП. Al шин 30 для FE S1. (4 конт. зоны по 30 мм), длиной до 999 мм | C33: шт | D33: 1 | E33: =G33/11 -> 42.175602 | F33: =11/G33 -> 0.023710391 | G33: =L33/H33 -> 463.93162 | H33: 1.2717391 | I33: =M33/L33 -> 1.1186441 | J33: =11/K33 -> 0.023913043 | K33: 460 | L33: 590 | M33: 660
A34: 00511 | B34: НАП. Al шин 50 для FE S1. (4 конт. зоны по 30 мм), длиной до 999 мм | C34: шт | D34: 1 | E34: =G34/11 -> 36.674437 | F34: =11/G34 -> 0.027266949 | G34: =L34/H34 -> 403.4188 | H34: 1.4625 | I34: =M34/L34 -> 1.1186441 | J34: =11/K34 -> 0.0275 | K34: 400 | L34: 590 | M34: 660
A35: 00512 | B35: НАП. Al шин 60 для FE S1. (4 конт. зоны по 30 мм), длиной до 999 мм | C35: шт | D35: 1 | E35: =G35/11 -> 33.465423 | F35: =11/G35 -> 0.029881588 | G35: =L35/H35 -> 368.11966 | H35: 1.6027397 | I35: =M35/L35 -> 1.1186441 | J35: =11/K35 -> 0.030136986 | K35: 365 | L35: 590 | M35: 660
A36: 00513 | B36: НАП. Al шин 65 для FE S1. (4 конт. зоны по 30 мм), длиной до 999 мм | C36: шт | D36: 1 | E36: =G36/11 -> 31.173271 | F36: =11/G36 -> 0.032078764 | G36: =L36/H36 -> 342.90598 | H36: 1.7205882 | I36: =M36/L36 -> 1.1186441 | J36: =11/K36 -> 0.032352941 | K36: 340 | L36: 590 | M36: 660
A37: 00514 | B37: НАП. Al шин 75 для FE S1. (4 конт. зоны по 30 мм), длиной до 999 мм | C37: шт | D37: 1 | E37: =G37/11 -> 27.505828 | F37: =11/G37 -> 0.036355932 | G37: =L37/H37 -> 302.5641 | H37: 1.95 | I37: =M37/L37 -> 1.1186441 | J37: =11/K37 -> 0.036666667 | K37: 300 | L37: 590 | M37: 660
A38: 00515 | B38: НАП. Al шин 100 для FE S1. (4 конт. зоны по 30 мм), длиной до 999 мм | C38: шт | D38: 1 | E38: =G38/11 -> 22.004662 | F38: =11/G38 -> 0.045444915 | G38: =L38/H38 -> 242.05128 | H38: 2.4375 | I38: =M38/L38 -> 1.1186441 | J38: =11/K38 -> 0.045833333 | K38: 240 | L38: 590 | M38: 660
A39: 00516 | B39: НАП. Al шин 109 для FE S1. (4 конт. зоны по 30 мм), длиной до 999 мм | C39: шт | D39: 1 | E39: =G39/11 -> 23.379953 | F39: =11/G39 -> 0.042771685 | G39: =L39/H39 -> 257.17949 | H39: 2.2941176 | I39: =M39/L39 -> 1.1186441 | J39: =11/K39 -> 0.043137255 | K39: 255 | L39: 590 | M39: 660
A40: 00517 | B40: НАП. Al шин 130 для FE S1. (4 конт. зоны по 30 мм), длиной до 999 мм | C40: шт | D40: 1 | E40: =G40/11 -> 18.337218 | F40: =11/G40 -> 0.054533898 | G40: =L40/H40 -> 201.7094 | H40: 2.925 | I40: =M40/L40 -> 1.1186441 | J40: =11/K40 -> 0.055 | K40: 200 | L40: 590 | M40: 660
...

Sheet СПРАВОЧНИК
A1: СПРАВОЧНИК
A2: Дополнительные работы | B2: Код
A3: Повременные работы | B3: 0000
A5: Заготовительные операции
A6: Участок напыления | B6: 500
A7: Авт. линия подготовки шин. Цех №2. | B7: 800
A8: Участок гибки | B8: 1000
A9: Участок заливки | B9: 1150
A10: Участок обработки | B10: 1300
A11: Резка на пиле | B11: 1400
A12: Зачистка | B12: 1470
A13: Участок покраски | B13: 1500
A14: Участок сварки | B14: 1600
A15: Участок станков с ПУ | B15: 1700
A16: Участок изолировки | B16: 1900
A18: Сборочные операции | B18: Код
A19: Участок сборки стыков | B19: 2000
A20: Участок сборки секций | B20: 2200
A21: Участок сборки секций ЛШП | B21: 2400
A22: Участок сборки ЯОМ | B22: 2700
A24: Упаковка ГП | B24: Код
A25: Упаковка | B25: 3000
A27: Специализированные изделия | B27: Код
A28: Гибкая шина плетеная | B28: 4000
A29: Устаревшие нормы | B29: Код
A30: Общий список | B30: 9000

Sheet форма для расчета
A1: Код расценки | B1: Полное наименование | C1: Базовая единица изм. | D1: Норма выработки за час, шт. | E1: Трудоем-кость, чел/час | F1: Количество изделий | G1: Заработан-ные, н/час
A2: 00977 | B2: =VLOOKUP(A2,БАЗА!A:F,2,0) -> ARM. ПС. FE 4000А. Полная сборка пакетов, соединение пакетов, упаковка и снятие. 4000А. | C2: =VLOOKUP(A2,БАЗА!A:G,3,0) -> шт | D2: =VLOOKUP(A2,БАЗА!A:G,5,0) -> 0.72727273 | E2: =VLOOKUP(A2,БАЗА!A:G,6,0) -> 1.375 | F2: 15 | G2: =IF(F2=0,0,F2*E2) -> 20.625
A3: 03000 | B3: =VLOOKUP(A3,БАЗА!A:F,2,0) -> Комплектовка и упаковка стандартных секций на поддон | C3: =VLOOKUP(A3,БАЗА!A:G,3,0) -> подддон | D3: =VLOOKUP(A3,БАЗА!A:G,5,0) -> 1.26 | E3: =VLOOKUP(A3,БАЗА!A:G,6,0) -> 0.79365079 | F3: 1 | G3: =IF(F3=0,0,F3*E3) -> 0.79365079
A4: 00004 | B4: =VLOOKUP(A4,БАЗА!A:F,2,0) -> Повременные работы. Сборка | C4: =VLOOKUP(A4,БАЗА!A:G,3,0) -> час | D4: =VLOOKUP(A4,БАЗА!A:G,5,0) -> 1 | E4: =VLOOKUP(A4,БАЗА!A:G,6,0) -> 1 | F4: 1 | G4: =IF(F4=0,0,F4*E4) -> 1
B5: =VLOOKUP(A5,БАЗА!A:F,2,0) -> #N/A | C5: =VLOOKUP(A5,БАЗА!A:G,3,0) -> #N/A | D5: =VLOOKUP(A5,БАЗА!A:G,5,0) -> #N/A | E5: =VLOOKUP(A5,БАЗА!A:G,6,0) -> #N/A | G5: =IF(F5=0,0,F5*E5) -> 0
B6: =VLOOKUP(A6,БАЗА!A:F,2,0) -> #N/A | C6: =VLOOKUP(A6,БАЗА!A:G,3,0) -> #N/A | D6: =VLOOKUP(A6,БАЗА!A:G,5,0) -> #N/A | E6: =VLOOKUP(A6,БАЗА!A:G,6,0) -> #N/A | G6: =IF(F6=0,0,F6*E6) -> 0
B7: =VLOOKUP(A7,БАЗА!A:F,2,0) -> #N/A | C7: =VLOOKUP(A7,БАЗА!A:G,3,0) -> #N/A | D7: =VLOOKUP(A7,БАЗА!A:G,5,0) -> #N/A | E7: =VLOOKUP(A7,БАЗА!A:G,6,0) -> #N/A | G7: =IF(F7=0,0,F7*E7) -> 0
B8: =VLOOKUP(A8,БАЗА!A:F,2,0) -> #N/A | C8: =VLOOKUP(A8,БАЗА!A:G,3,0) -> #N/A | D8: =VLOOKUP(A8,БАЗА!A:G,5,0) -> #N/A | E8: =VLOOKUP(A8,БАЗА!A:G,6,0) -> #N/A | G8: =IF(F8=0,0,F8*E8) -> 0
B9: =VLOOKUP(A9,БАЗА!A:F,2,0) -> #N/A | C9: =VLOOKUP(A9,БАЗА!A:G,3,0) -> #N/A | D9: =VLOOKUP(A9,БАЗА!A:G,5,0) -> #N/A | E9: =VLOOKUP(A9,БАЗА!A:G,6,0) -> #N/A | G9: =IF(F9=0,0,F9*E9) -> 0
B10: =VLOOKUP(A10,БАЗА!A:F,2,0) -> #N/A | C10: =VLOOKUP(A10,БАЗА!A:G,3,0) -> #N/A | D10: =VLOOKUP(A10,БАЗА!A:G,5,0) -> #N/A | E10: =VLOOKUP(A10,БАЗА!A:G,6,0) -> #N/A | G10: =IF(F10=0,0,F10*E10) -> 0
B11: =VLOOKUP(A11,БАЗА!A:F,2,0) -> #N/A | C11: =VLOOKUP(A11,БАЗА!A:G,3,0) -> #N/A | D11: =VLOOKUP(A11,БАЗА!A:G,5,0) -> #N/A | E11: =VLOOKUP(A11,БАЗА!A:G,6,0) -> #N/A | G11: =IF(F11=0,0,F11*E11) -> 0
B12: =VLOOKUP(A12,БАЗА!A:F,2,0) -> #N/A | C12: =VLOOKUP(A12,БАЗА!A:G,3,0) -> #N/A | D12: =VLOOKUP(A12,БАЗА!A:G,5,0) -> #N/A | E12: =VLOOKUP(A12,БАЗА!A:G,6,0) -> #N/A | G12: =IF(F12=0,0,F12*E12) -> 0
B13: =VLOOKUP(A13,БАЗА!A:F,2,0) -> #N/A | C13: =VLOOKUP(A13,БАЗА!A:G,3,0) -> #N/A | D13: =VLOOKUP(A13,БАЗА!A:G,5,0) -> #N/A | E13: =VLOOKUP(A13,БАЗА!A:G,6,0) -> #N/A | G13: =IF(F13=0,0,F13*E13) -> 0
B14: =VLOOKUP(A14,БАЗА!A:F,2,0) -> #N/A | C14: =VLOOKUP(A14,БАЗА!A:G,3,0) -> #N/A | D14: =VLOOKUP(A14,БАЗА!A:G,5,0) -> #N/A | E14: =VLOOKUP(A14,БАЗА!A:G,6,0) -> #N/A | G14: =IF(F14=0,0,F14*E14) -> 0
B15: =VLOOKUP(A15,БАЗА!A:F,2,0) -> #N/A | C15: =VLOOKUP(A15,БАЗА!A:G,3,0) -> #N/A | D15: =VLOOKUP(A15,БАЗА!A:G,5,0) -> #N/A | E15: =VLOOKUP(A15,БАЗА!A:G,6,0) -> #N/A | G15: =IF(F15=0,0,F15*E15) -> 0
B16: =VLOOKUP(A16,БАЗА!A:F,2,0) -> #N/A | C16: =VLOOKUP(A16,БАЗА!A:G,3,0) -> #N/A | D16: =VLOOKUP(A16,БАЗА!A:G,5,0) -> #N/A | E16: =VLOOKUP(A16,БАЗА!A:G,6,0) -> #N/A | G16: =IF(F16=0,0,F16*E16) -> 0
... B23: =VLOOKUP(A23,БАЗА!A:F,2,0) -> #N/A | C23: =VLOOKUP(A23,БАЗА!A:G,3,0) -> #N/A | D23: =VLOOKUP(A23,БАЗА!A:G,5,0) -> #N/A | E23: =VLOOKUP(A23,БАЗА!A:G,6,0) -> #N/A | G23: =IF(F23=0,0,F23*E23) -> 0
A24: Итого (ощее число) | G24: =SUM(G2:G23) -> 22.418651
A25: Итого (на каждого, если двое) | G25: =G24/2 -> 11.209325

Sheet Последние изменения
B1: Изменения относительно предыдущей версии
A2: КОД | B2: Описание | C2: Измеритель | D2: Кол-во исп. | E2: Норма в час (н. в см./11) | F2: Трудоем-кость, чел/час | G2: Норма выраб.за смену, шт | H2: Штучно-калькуляционное время, мин
B3: Гибка стандартного и нестандартного угла
A4: 11063 | B4: Г Кр CD. Гибка крышки пакета стандартного и нестандартного горизонтального угла (1 пакет шин) | C4: крышка | E4: 21.6 | F4: 0.046296296 | G4: 237.6 | H4: 2.5252525
A5: 11064 | B5: Г Пк CD. Гибка полукорпуса пакета стандартного и нестандартного горизонтального угла (1 пакет шин) | C5: полукорпус | E5: 21.6 | F5: 0.046296296 | G5: 237.6 | H5: 2.5252525
A6: 11065 | B6: Г Кр CP. Гибка крышки пакета стандартного и нестандартного вертикального угла (1 пакет шин) | C6: крышка | E6: 21.6 | F6: 0.046296296 | G6: 237.6 | H6: 2.5252525
A7: 11066 | B7: Г Пк CP. Гибка полукорпуса пакета стандартного и нестандартного вертикального угла (1 пакет шин) | C7: полукорпус | E7: 21.6 | F7: 0.046296296 | G7: 237.6 | H7: 2.5252525
B8: Изготовление гибкой шины плетеной KLM-C, подготовительные операции. | D8: 1
A9: 40111 | B9: ГШП 1.11.1.М Лужение зачищенной контактной площадки (без косички) ширина до 100 мм | C9: шт | E9: 18.181818 | F9: 0.055 | G9: 200 | H9: 3
A10: 40112 | B10: ГШП 1.12.1.Б Лужение зачищенной контактной площадки (без косички) ширина более 100 мм | C10: шт | E10: 13.636364 | F10: 0.073333333 | G10: 150 | H10: 4
A11: 40115 | B11: Лужение зачищенных контактных площадок. (для ЯОМ) | C11: шт | D11: 1 | E11: 27.272727 | F11: 0.036666667 | G11: 300 | H11: 2
B12: Z,P-модуль магистрального шинопровода:
A13: 11003 | B13: Г Кр ZD. Гибка крышки пакета стандартного и нестандартного горизонтального Z модуля (1 пакет шин) | C13: крышка | E13: 10.363636 | F13: 0.096491228 | G13: 114 | H13: 5.2631579
A14: 11004 | B14: Г Пк ZD. Гибка полукорпуса пакета стандартного и нестандартного горизонтального Z модуля (1 пакет шин) | C14: полукорпус | E14: 10.363636 | F14: 0.096491228 | G14: 114 | H14: 5.2631579
A15: 11005 | B15: Г Кр ZP. Гибка крышки пакета стандартного и нестандартного вертикального Z модуля (1 пакет шин) | C15: крышка | E15: 10.363636 | F15: 0.096491228 | G15: 114 | H15: 5.2631579
A16: 11006 | B16: Г Пк ZP. Гибка полукорпуса пакета стандартного и нестандартного вертикального Z модуля (1 пакет шин) | C16: полукорпус | E16: 10.363636 | F16: 0.096491228 | G16: 114 | H16: 5.2631579
B17: Лазерная сварка Al шин (без расходных материалов)
A18: 01642 | B18: MAX .Сварка Al шин толщинойс двух сторон (с переворотом). Ширина шин 30-65 мм, | C18: шов | D18: 1 | E18: 25 | F18: 0.04 | G18: 275 | H18: 2
A19: 01643 | B19: MAX .Сварка Al шин толщинойс двух сторон (с переворотом). Ширина шин 75-100 мм, | C19: шов | D19: 1 | E19: 20.833333 | F19: 0.048 | G19: 229.16667 | H19: 2.4
A20: 01644 | B20: MAX .Сварка Al шин толщинойс двух сторон (с переворотом). Ширина шин 130 мм, | C20: шов | D20: 1 | E20: 13.888889 | F20: 0.072 | G20: 152.77778 | H20: 3.6
A21: 01645 | B21: MAX .Сварка Al шин толщинойс двух сторон (с переворотом). Ширина шин 160 мм, | C21: шов | D21: 1 | E21: 10.416667 | F21: 0.096 | G21: 114.58333 | H21: 4.8
A22: 01646 | B22: MAX .Сварка Al шин толщинойс двух сторон (с переворотом). Ширина шин 200 мм, | C22: шов | D22: 1 | E22: 8.3333333 | F22: 0.12 | G22: 91.666667 | H22: 6
B23: Обработка КША после сварки (с помощью УШМ)
A24: 01652 | B24: Обработка КША после сварки. Шины равны по ширине пакету. (2 шва на 1 КША). | C24: шов | D24: 1 | E24: 8.9393939 | F24: 0.11186441 | G24: 98.333333 | H24: 6
A25: 01653 | B25: Обработка КША после сварки. Шины не равны по ширине пакету. (2 шва на 1 КША). | C25: шов | D25: 1 | E25: 6.7045455 | F25: 0.14915254 | G25: 73.75 | H25: 8
B26: Резка боковин под прямым углом | F26: #DIV/0!
A27: 01430 | B27: Y. РПБ 53 FE. Резка боковин из Al профиля стандартной длины (3 метра), высотой 53 мм. Зачистка торцов от заусенцев, . Снятие фаски (и краски) на наружных углах ручным шабером. | C27: шт | D27: 1 | E27: 28.06558 | F27: 0.035630833 | G27: 308.72138 | H27: 1.9435
A28: 01431 | B28: Y. РПБ 53 FE-S. Резка боковин из Al профиля Нестандартной длины (3 метра), высотой 53 мм. Зачистка торцов от заусенцев. | C28: шт | D28: 1 | E28: 25.518341 | F28: 0.0391875 | G28: 280.70175 | H28: 2.1375
A29: 01432 | B29: Y. РПБ 68 FE. Резка боковин из Al профиля стандартной длины (3 метра), высотой 68 мм. Зачистка торцов от заусенцев, . Снятие фаски (и краски) на наружных углах ручным шабером. | C29: шт | D29: 1 | E29: 26.719631 | F29: 0.037425667 | G29: 293.91594 | H29: 2.0414
A30: 01433 | B30: Y. РПБ 68 FE-S. Резка боковин из Al профиля Нестандартной длины (3 метра), высотой 68 мм. Зачистка торцов от заусенцев. | C30: шт | D30: 1 | E30: 24.350649 | F30: 0.041066667 | G30: 267.85714 | H30: 2.24
A31: 01434 | B31: Y. РПБ 78 FE. Резка боковин из Al профиля стандартной длины (3 метра), высотой 78 мм. Зачистка торцов от заусенцев, . Снятие фаски (и краски) на наружных углах ручным шабером. | C31: шт | D31: 1 | E31: 24.653313 | F31: 0.0405625 | G31: 271.18644 | H31: 2.2125
A32: 01435 | B32: Y. РПБ 78 FE-S. Резка боковин из Al профиля Нестандартной длины (3 метра), высотой 78 мм. Зачистка торцов от заусенцев. | C32: шт | D32: 1 | E32: 22.57209 | F32: 0.0443025 | G32: 248.29299 | H32: 2.4165
A33: 01436 | B33: Y. РПБ 103 FE. Резка боковин из Al профиля стандартной длины (3 метра), высотой 103 мм. Зачистка торцов от заусенцев, . Снятие фаски (и краски) на наружных углах ручным шабером. | C33: шт | D33: 1 | E33: 22.116256 | F33: 0.04521561 | G33: 243.27881 | H33: 2.466306
A34: 01437 | B34: Y. РПБ 103 FE-S. Резка боковин из Al профиля Нестандартной длины (3 метра), высотой 103 мм. Зачистка торцов от заусенцев. | C34: шт | D34: 1 | E34: 20.539043 | F34: 0.04868776 | G34: 225.92947 | H34: 2.655696
A35: 01438 | B35: Y. РПБ 133 FE. Резка боковин из Al профиля стандартной длины (3 метра), высотой 133 мм. Зачистка торцов от заусенцев, . Снятие фаски (и краски) на наружных углах ручным шабером. | C35: шт | D35: 1 | E35: 21.638067 | F35: 0.04621485 | G35: 238.01873 | H35: 2.52081
A36: 01439 | B36: Y. РПБ 133 FE-S. Резка боковин из Al профиля Нестандартной длины (3 метра), высотой 133 мм. Зачистка торцов от заусенцев. | C36: шт | D36: 1 | E36: 20.099705 | F36: 0.049751973 | G36: 221.09676 | H36: 2.713744
A37: 01440 | B37: Y. РПБ 163 FE. Резка боковин из Al профиля стандартной длины (3 метра), высотой 163 мм. Зачистка торцов от заусенцев, . Снятие фаски (и краски) на наружных углах ручным шабером. | C37: шт | D37: 1 | E37: 16.669571 | F37: 0.059989545 | G37: 183.36528 | H37: 3.272157
A38: 01441 | B38: Y. РПБ 163 FE-S. Резка боковин из Al профиля Нестандартной длины (3 метра), высотой 163 мм. Зачистка торцов от заусенцев. | C38: шт | D38: 1 | E38: 15.206512 | F38: 0.0657613 | G38: 167.27163 | H38: 3.58698
... A40: 01443 | B40: Y. РПБ 203 FE-S. Резка боковин из Al профиля Нестандартной длины (3 метра), высотой 203 мм. Зачистка торцов от заусенцев. | C40: шт | D40: 1 | E40: 11.264509 | F40: 0.0887744 | G40: 123.9096 | H40: 4.84224
B41: Крышки для автоматической сборочной линии
...
