Workbook

Sheet Стандартные размеры KLM-S
A1: Габаритные размеры шинопровода KLM-S, IP55 конструктива 13/V3
D3: Таблица размеров и масс
D4: Секция угловая горизонтальная FE
D5: Рекомендуемая кратность шага
D6: Шаг L1 = | G6: 10 мм.
A8: Номинальный ток | B8: 4р | N8: 5р
B9: алюминий | H9: медь | N9: алюминий | T9: медь
B10: H, мм | C10: W, мм | D10: Шина | G10: Масса, кг пог/м | H10: H, мм | I10: W, мм | J10: Шина | M10: Масса, кг пог/м | N10: H, мм | O10: W, мм | P10: Шина | S10: Масса, кг пог/м | T10: H, мм | U10: W, мм | V10: Шина | Y10: Масса, кг пог/м
D11: Кол-во, шт | E11: Высота | F11: Толщина | J11: Кол-во, шт | K11: Высота | L11: Толщина | P11: Кол-во, шт | Q11: Высота | R11: Толщина | V11: Кол-во, шт | W11: Высота | X11: Толщина
A12: 160 | B12: =E12+18+18+3 -> 69 | C12: 140 | D12: 1 | E12: 30 | F12: 6 | G12: 7.5 | H12: =K12+18+18+3 -> 69 | I12: 140 | J12: 1 | K12: 30 | L12: 6 | M12: 18.4 | N12: =B12 -> 69 | O12: =C12 -> 140 | P12: =D12 -> 1 | Q12: =E12 -> 30 | R12: =F12 -> 6 | S12: 8.7 | T12: =H12 -> 69 | U12: =C12 -> 140 | V12: =J12 -> 1 | W12: =K12 -> 30 | X12: =L12 -> 6 | Y12: 20.5
A13: 250 | B13: =E13+18+18+3 -> 69 | C13: 140 | D13: 1 | E13: 30 | F13: 6 | G13: 7.5 | H13: =K13+18+18+3 -> 69 | I13: 140 | J13: 1 | K13: 30 | L13: 6 | M13: 18.4 | N13: =B13 -> 69 | O13: =C13 -> 140 | P13: =D13 -> 1 | Q13: =E13 -> 30 | R13: =F13 -> 6 | S13: 8.7 | T13: =H13 -> 69 | U13: =C13 -> 140 | V13: =J13 -> 1 | W13: =K13 -> 30 | X13: =L13 -> 6 | Y13: 20.5
A14: 315 | B14: =E14+18+18+3 -> 69 | C14: 140 | D14: 1 | E14: 30 | F14: 6 | G14: 7.5 | H14: =K14+18+18+3 -> 69 | I14: 140 | J14: 1 | K14: 30 | L14: 6 | M14: 18.4 | N14: =B14 -> 69 | O14: =C14 -> 140 | P14: =D14 -> 1 | Q14: =E14 -> 30 | R14: =F14 -> 6 | S14: 8.7 | T14: =H14 -> 69 | U14: =C14 -> 140 | V14: =J14 -> 1 | W14: =K14 -> 30 | X14: =L14 -> 6 | Y14: 20.5
A15: 400 | B15: =E15+18+18+3 -> 69 | C15: 140 | D15: 1 | E15: 30 | F15: 6 | G15: 7.5 | H15: =K15+18+18+3 -> 69 | I15: 140 | J15: 1 | K15: 30 | L15: 6 | M15: 18.4 | N15: =B15 -> 69 | O15: =C15 -> 140 | P15: =D15 -> 1 | Q15: =E15 -> 30 | R15: =F15 -> 6 | S15: 8.7 | T15: =H15 -> 69 | U15: =C15 -> 140 | V15: =J15 -> 1 | W15: =K15 -> 30 | X15: =L15 -> 6 | Y15: 20.5
A16: 500 | B16: =E16+18+18+3 -> 79 | C16: 140 | D16: 1 | E16: 40 | F16: 6 | G16: 7.5 | H16: =K16+18+18+3 -> 69 | I16: 140 | J16: 1 | K16: 30 | L16: 6 | M16: 18.4 | N16: =B16 -> 79 | O16: =C16 -> 140 | P16: =D16 -> 1 | Q16: =E16 -> 40 | R16: =F16 -> 6 | S16: =G16 -> 7.5 | T16: =H16 -> 69 | U16: =I16 -> 140 | ... Y16: =M16 -> 18.4
A17: 630 | B17: =E17+18+18+3 -> 89 | C17: 140 | D17: 1 | E17: 50 | F17: 6 | G17: 9.4 | H17: =K17+18+18+3 -> 79 | I17: =C17 -> 140 | J17: 1 | K17: 40 | L17: 6 | M17: 20.6 | N17: =B17 -> 89 | O17: =C17 -> 140 | P17: =D17 -> 1 | Q17: =E17 -> 50 | R17: =F17 -> 6 | S17: 10.9 | T17: =H17 -> 79 | U17: =C17 -> 140 | V17: =J17 -> 1 | W17: =K17 -> 40 | X17: =L17 -> 6 | Y17: 23
A18: 800 | B18: =E18+18+18+3 -> 104 | C18: =C17 -> 140 | D18: 1 | E18: 65 | F18: 6 | G18: 10.7 | H18: =K18+18+18+3 -> 99 | I18: =C18 -> 140 | J18: 1 | K18: 60 | L18: =L17 -> 6 | M18: 20.6 | N18: =B18 -> 104 | O18: =C18 -> 140 | P18: =D18 -> 1 | Q18: =E18 -> 65 | R18: =F18 -> 6 | S18: 12.3 | T18: =H18 -> 99 | U18: =C18 -> 140 | V18: =J18 -> 1 | W18: =K18 -> 60 | X18: =L18 -> 6 | Y18: 23
A19: 1000 | B19: =E19+18+18+3 -> 139 | C19: =C18 -> 140 | D19: 1 | E19: 100 | F19: 6 | G19: 12.9 | H19: =K19+18+18+3 -> 104 | I19: =C19 -> 140 | J19: 1 | K19: 65 | L19: =L18 -> 6 | M19: 22.6 | N19: =B19 -> 139 | O19: =C19 -> 140 | P19: =D19 -> 1 | Q19: =E19 -> 100 | R19: =F19 -> 6 | S19: 13.7 | T19: =H19 -> 104 | U19: =C19 -> 140 | V19: =J19 -> 1 | W19: =K19 -> 65 | X19: =L19 -> 6 | Y19: 25.6
A20: 1250 | B20: =E20+18+18+3 -> 169 | C20: =C19 -> 140 | D20: 1 | E20: 130 | F20: 6 | G20: 15.9 | H20: =K20+18+18+3 -> 119 | I20: =C20 -> 140 | J20: 1 | K20: 80 | L20: =L19 -> 6 | M20: 25.6 | N20: =B20 -> 169 | O20: =C20 -> 140 | P20: =D20 -> 1 | Q20: =E20 -> 130 | R20: =F20 -> 6 | S20: 18.8 | T20: =H20 -> 119 | U20: =C20 -> 140 | V20: 1 | W20: =K20 -> 80 | X20: =L20 -> 6 | Y20: 28.6
A21: 1600 | B21: =E21+18+18+3 -> 199 | C21: =C20 -> 140 | D21: 1 | E21: 160 | F21: 6 | G21: 19.4 | H21: =K21+18+18+3 -> 139 | I21: =C21 -> 140 | J21: 1 | K21: 100 | L21: =L20 -> 6 | M21: 30.9 | N21: =B21 -> 199 | O21: =C21 -> 140 | P21: =D21 -> 1 | Q21: =E21 -> 160 | R21: =F21 -> 6 | S21: 23.1 | T21: =H21 -> 139 | U21: =C21 -> 140 | V21: 1 | W21: =K21 -> 100 | X21: =L21 -> 6 | Y21: 36.9
A22: 2000 | B22: =E22+18+18+3 -> 239 | C22: =C21 -> 140 | D22: 1 | E22: 200 | F22: 6 | G22: 23.3 | H22: =K22+18+18+3 -> 199 | I22: =C22 -> 140 | J22: 1 | K22: 160 | L22: =L21 -> 6 | M22: 38.8 | N22: =B22 -> 239 | O22: =C22 -> 140 | P22: =D22 -> 1 | Q22: =E22 -> 200 | R22: =F22 -> 6 | S22: 27.5 | T22: =H22 -> 199 | U22: =C22 -> 140 | V22: 1 | W22: =K22 -> 160 | X22: =L22 -> 6 | Y22: 46.8
A23: 2500 | B23: =(E23*D23)+18+18+(3*D23)+(3*D23)+40 -> 348 | C23: =C22 -> 140 | D23: 2 | E23: 130 | F23: 6 | G23: 33.66 | H23: =K23+18+18+3 -> 239 | I23: =C23 -> 140 | J23: 1 | K23: 200 | L23: =L22 -> 6 | M23: 46.6 | N23: =B23 -> 348 | O23: =C23 -> 140 | P23: =D23 -> 2 | Q23: =E23 -> 130 | R23: =F23 -> 6 | S23: 39.3 | T23: =H23 -> 239 | U23: =C23 -> 140 | V23: 1 | W23: =K23 -> 200 | X23: =L23 -> 6 | Y23: 49.8
A24: 3200 | B24: =(E24*D24)+18+18+(3*D24)+(3*D24)+40 -> 408 | C24: =C23 -> 140 | D24: 2 | E24: 160 | F24: 6 | G24: 39.5 | H24: =(K24*J24)+18+18+(3*J24)+(3*J24)+40 -> 348 | I24: =C24 -> 140 | J24: 2 | K24: 130 | L24: =L23 -> 6 | M24: 62.6 | N24: =B24 -> 408 | O24: =C24 -> 140 | P24: =D24 -> 2 | Q24: =E24 -> 160 | R24: =F24 -> 6 | S24: 46.3 | T24: =H24 -> 348 | U24: =C24 -> 140 | V24: =J24 -> 2 | W24: =K24 -> 130 | X24: =L24 -> 6 | Y24: 74.8
A25: 4000 | B25: =(E25*D25)+18+18+(3*D25)+(3*D25)+40 -> 488 | C25: =C24 -> 140 | D25: 2 | E25: 200 | F25: 6 | G25: 47.5 | H25: =(K25*J25)+18+18+(3*J25)+(3*J25)+40 -> 408 | I25: =C25 -> 140 | J25: 2 | K25: 160 | L25: =L24 -> 6 | M25: 93.9 | N25: =B25 -> 488 | O25: =C25 -> 140 | P25: =D25 -> 2 | Q25: =E25 -> 200 | R25: =F25 -> 6 | S25: 55.3 | T25: =H25 -> 408 | U25: =C25 -> 140 | V25: =J25 -> 2 | W25: =K25 -> 160 | X25: =L25 -> 6 | Y25: 114.7
A26: 5000 | B26: =(E26*D26)+18+18+(3*6)+(3*D26)+(40*3) -> 706 | C26: =C25 -> 140 | D26: 4 | E26: 130 | F26: 6 | G26: 67.4 | H26: =(K26*J26)+18+18+(3*J26)+(3*J26)+40 -> 488 | I26: =C26 -> 140 | J26: 2 | K26: 200 | L26: =L25 -> 6 | M26: 124.6 | N26: =B26 -> 706 | O26: =C26 -> 140 | P26: =D26 -> 4 | Q26: =E26 -> 130 | R26: =F26 -> 6 | S26: 77.3 | T26: =H26 -> 488 | U26: =C26 -> 140 | V26: =J26 -> 2 | W26: =K26 -> 200 | X26: =L26 -> 6 | Y26: 152.6
A27: 6300 | B27: =(E27*D27)+18+18+(3*6)+(3*D27)+(40*3) -> 826 | C27: =C26 -> 140 | D27: 4 | E27: 160 | F27: 6 | G27: 74.7 | H27: =(K27*J27)+18+18+(3*4)+(3*J27)+40*2 -> 737 | I27: =C27 -> 140 | J27: 3 | K27: 200 | L27: =L26 -> 6 | M27: 156.1 | N27: =B27 -> 826 | O27: =C27 -> 140 | P27: =D27 -> 4 | Q27: =E27 -> 160 | R27: =F27 -> 6 | S27: 90.7 | T27: =H27 -> 737 | U27: =C27 -> 140 | V27: =J27 -> 3 | W27: =K27 -> 200 | X27: =L27 -> 6 | Y27: 168.1
A28: *Pi (окна только на одной стороне секции) | B28: до 1000мм без окон окона отбора мощности
B29: от 1000-2000мм 1 оконо отбора мощности
B30: 3000мм 2 окона отбора мощности
A34: Габаритные размеры шинопровода KLM-S, IP68 конструктива 13/V3
D36: Таблица размеров и масс
D37: Секция угловая горизонтальная FE
D38: Рекомендуемая кратность шага
D39: Шаг L1 = | G39: 10 мм.
A41: Номинальный ток | B41: 4р | N41: 5р
B42: алюминий | H42: медь | N42: алюминий | T42: медь
B43: H, мм | C43: W, мм | D43: Шина | G43: Масса, кг пог/м | H43: H, мм | I43: W, мм | J43: Шина | M43: Масса, кг пог/м | N43: H, мм | O43: W, мм | P43: Шина | S43: Масса, кг пог/м | T43: H, мм | U43: W, мм | V43: Шина | Y43: Масса, кг пог/м
D44: Кол-во, шт | E44: Высота | F44: Толщина | J44: Кол-во, шт | K44: Высота | L44: Толщина | P44: Кол-во, шт | Q44: Высота | R44: Толщина | V44: Кол-во, шт | W44: Высота | X44: Толщина
A45: 160 | B45: =E45+16.5+16.5+6 -> 69 | C45: 140 | D45: 1 | E45: 30 | F45: 6 | H45: =K45+18+18+3 -> 69 | I45: 140 | J45: 1 | K45: 30 | L45: 6 | N45: =B45 -> 69 | O45: =C45 -> 140 | P45: =D45 -> 1 | Q45: =E45 -> 30 | R45: =F45 -> 6 | T45: =H45 -> 69 | U45: =C45 -> 140 | V45: =J45 -> 1 | W45: =K45 -> 30 | X45: =L45 -> 6
A46: 250 | B46: =E46+16.5+16.5+6 -> 69 | C46: 140 | D46: 1 | E46: 30 | F46: 6 | H46: =K46+18+18+3 -> 69 | I46: 140 | J46: 1 | K46: 30 | L46: 6 | N46: =B46 -> 69 | O46: =C46 -> 140 | P46: =D46 -> 1 | Q46: =E46 -> 30 | R46: =F46 -> 6 | T46: =H46 -> 69 | U46: =C46 -> 140 | V46: =J46 -> 1 | W46: =K46 -> 30 | X46: =L46 -> 6
A47: 315 | B47: =E47+16.5+16.5+6 -> 69 | C47: 140 | D47: 1 | E47: 30 | F47: 6 | H47: =K47+18+18+3 -> 69 | I47: 140 | J47: 1 | K47: 30 | L47: 6 | N47: =B47 -> 69 | O47: =C47 -> 140 | P47: =D47 -> 1 | Q47: =E47 -> 30 | R47: =F47 -> 6 | T47: =H47 -> 69 | U47: =C47 -> 140 | V47: =J47 -> 1 | W47: =K47 -> 30 | X47: =L47 -> 6
...

Sheet Можно удалить 68
A1: Габаритные размеры шинопровода KLM-S с конструктива 13/V3
D3: Таблица размеров и масс
D4: Секция угловая горизонтальная FE
D5: Рекомендуемая кратность шага
D6: Шаг L1 = | G6: 10 мм.
A8: Номинальный ток | B8: 4р | N8: 5р
B9: алюминий | H9: медь | N9: алюминий | T9: медь
B10: H, мм | C10: W, мм | D10: Шина | G10: Масса, кг пог/м | H10: H, мм | I10: W, мм | J10: Шина | M10: Масса, кг пог/м | N10: H, мм | O10: W, мм | P10: Шина | S10: Масса, кг пог/м | T10: H, мм | U10: W, мм | V10: Шина | Y10: Масса, кг пог/м
D11: Кол-во, шт | E11: Высота | F11: Толщина | J11: Кол-во, шт | K11: Высота | L11: Толщина | P11: Кол-во, шт | Q11: Высота | R11: Толщина | V11: Кол-во, шт | W11: Высота | X11: Толщина
A12: 160
A13: 250
A14: 400
A15: 630 | B15: =E15+16.5+16.5+6 -> 89 | C15: ='Стандартные размеры KLM-S'!C17 -> 140 | D15: 1 | E15: ='Стандартные размеры KLM-S'!E17 -> 50 | F15: ='Стандартные размеры KLM-S'!F17 -> 6 | G15: 23.2 | H15: =K15+16.5+16.5+6 -> 79 | I15: =C15 -> 140 | J15: 1 | K15: ='[1]Стандартные размеры'!K18 -> 40 | L15: 6 | M15: 28.9 | N15: =B15 -> 89 | O15: =C15 -> 140 | P15: 1 | Q15: =E15 -> 50 | R15: =F15 -> 6 | S15: 25.2 | T15: =H15 -> 79 | U15: =C15 -> 140 | V15: 1 | W15: =K15 -> 40 | X15: =L15 -> 6 | Y15: 32.7
A16: 800 | B16: =E16+16.5+16.5+6 -> 104 | C16: ='Стандартные размеры KLM-S'!C18 -> 140 | D16: 1 | E16: ='Стандартные размеры KLM-S'!E18 -> 65 | F16: ='Стандартные размеры KLM-S'!F18 -> 6 | G16: 24 | H16: =K16+16.5+16.5+6 -> 99 | I16: =C16 -> 140 | J16: 1 | K16: ='[1]Стандартные размеры'!K19 -> 60 | L16: =L15 -> 6 | M16: 31 | N16: =B16 -> 104 | O16: =C16 -> 140 | P16: 1 | Q16: =E16 -> 65 | R16: =F16 -> 6 | S16: 26.3 | T16: =H16 -> 99 | U16: =C16 -> 140 | V16: 1 | W16: =K16 -> 60 | X16: =L16 -> 6 | Y16: 35.5
A17: 1000 | B17: =E17+16.5+16.5+6 -> 139 | C17: ='Стандартные размеры KLM-S'!C19 -> 140 | D17: 1 | E17: ='Стандартные размеры KLM-S'!E19 -> 100 | F17: ='Стандартные размеры KLM-S'!F19 -> 6 | G17: 26.3 | H17: =K17+16.5+16.5+6 -> 104 | I17: =C17 -> 140 | J17: 1 | K17: ='[1]Стандартные размеры'!K20 -> 65 | L17: =L16 -> 6 | M17: 32.5 | N17: =B17 -> 139 | O17: =C17 -> 140 | P17: 1 | Q17: =E17 -> 100 | R17: =F17 -> 6 | S17: 28 | T17: =H17 -> 104 | U17: =C17 -> 140 | V17: 1 | W17: =K17 -> 65 | X17: =L17 -> 6 | Y17: 36.9
A18: 1250 | B18: =E18+16.5+16.5+6 -> 169 | C18: ='Стандартные размеры KLM-S'!C20 -> 140 | D18: 1 | E18: ='Стандартные размеры KLM-S'!E20 -> 130 | F18: ='Стандартные размеры KLM-S'!F20 -> 6 | G18: 30.8 | H18: =K18+16.5+16.5+6 -> 119 | I18: =C18 -> 140 | J18: 1 | K18: ='[1]Стандартные размеры'!K21 -> 80 | L18: =L17 -> 6 | M18: 34.3 | N18: =B18 -> 169 | O18: =C18 -> 140 | P18: 1 | Q18: =E18 -> 130 | R18: =F18 -> 6 | S18: 33.3 | T18: =H18 -> 119 | U18: =C18 -> 140 | V18: 1 | W18: =K18 -> 80 | X18: =L18 -> 6 | Y18: 38.7
A19: 1600 | B19: =E19+16.5+16.5+6 -> 199 | C19: ='Стандартные размеры KLM-S'!C21 -> 140 | D19: 1 | E19: ='Стандартные размеры KLM-S'!E21 -> 160 | F19: ='Стандартные размеры KLM-S'!F21 -> 6 | G19: 35.3 | H19: =K19+16.5+16.5+6 -> 139 | I19: =C19 -> 140 | J19: 1 | K19: ='[1]Стандартные размеры'!K22 -> 100 | L19: =L18 -> 6 | M19: 43 | N19: =B19 -> 199 | O19: =C19 -> 140 | P19: 1 | Q19: =E19 -> 160 | R19: =F19 -> 6 | S19: 36.7 | T19: =H19 -> 139 | U19: =C19 -> 140 | V19: 1 | W19: =K19 -> 100 | X19: =L19 -> 6 | Y19: 49
A20: 2000 | B20: =E20+16.5+16.5+6 -> 239 | C20: ='Стандартные размеры KLM-S'!C22 -> 140 | D20: 1 | E20: ='Стандартные размеры KLM-S'!E22 -> 200 | F20: ='Стандартные размеры KLM-S'!F22 -> 6 | G20: 41.3 | H20: =K20+16.5+16.5+6 -> 199 | I20: =C20 -> 140 | J20: 1 | K20: ='[1]Стандартные размеры'!K23 -> 160 | L20: =L19 -> 6 | M20: 53.3 | N20: =B20 -> 239 | O20: =C20 -> 140 | P20: 1 | Q20: =E20 -> 200 | R20: =F20 -> 6 | S20: 46.7 | T20: =H20 -> 199 | U20: =C20 -> 140 | V20: 1 | W20: =K20 -> 160 | X20: =L20 -> 6 | Y20: 61.3
A21: 2500 | B21: =(E21*D21)+(16.5*4)+(3*4)+15 -> 353 | C21: ='Стандартные размеры KLM-S'!C23 -> 140 | D21: 2 | E21: ='Стандартные размеры KLM-S'!E23 -> 130 | F21: ='Стандартные размеры KLM-S'!F23 -> 6 | G21: 55.3 | H21: =K21+16.5+16.5+6 -> 239 | I21: =C21 -> 140 | J21: 1 | K21: ='[1]Стандартные размеры'!K24 -> 200 | L21: =L20 -> 6 | M21: 62.7 | N21: =B21 -> 353 | O21: =C21 -> 140 | P21: =D21 -> 2 | Q21: =E21 -> 130 | R21: =F21 -> 6 | S21: 61.7 | T21: =H21 -> 239 | U21: =C21 -> 140 | V21: 1 | W21: =K21 -> 200 | X21: =L21 -> 6 | Y21: 72.7
A22: 3200 | B22: =(E22*D22)+(16.5*4)+(3*4)+15 -> 413 | C22: ='Стандартные размеры KLM-S'!C24 -> 140 | D22: 2 | E22: ='Стандартные размеры KLM-S'!E24 -> 160 | F22: ='Стандартные размеры KLM-S'!F24 -> 6 | G22: 66.2 | H22: =(K22*J22)+(16.5*4)+(3*4)+15 -> 353 | I22: =C22 -> 140 | J22: 2 | K22: ='[1]Стандартные размеры'!K25 -> 130 | L22: =L21 -> 6 | M22: 90 | N22: =B22 -> 413 | O22: =C22 -> 140 | P22: =D22 -> 2 | Q22: =E22 -> 160 | R22: =F22 -> 6 | S22: 70.3 | T22: =H22 -> 353 | U22: =C22 -> 140 | V22: =J22 -> 2 | W22: =K22 -> 130 | X22: =L22 -> 6 | Y22: 100
A23: 4000 | B23: =(E23*D23)+(16.5*4)+(3*4)+15 -> 493 | C23: ='Стандартные размеры KLM-S'!C25 -> 140 | D23: 2 | E23: ='Стандартные размеры KLM-S'!E25 -> 200 | F23: ='Стандартные размеры KLM-S'!F25 -> 6 | G23: 80.5 | H23: =(K23*J23)+(16.5*4)+(3*4)+15 -> 413 | I23: =C23 -> 140 | J23: 2 | K23: ='[1]Стандартные размеры'!K26 -> 160 | L23: =L22 -> 6 | M23: 122.7 | N23: =B23 -> 493 | O23: =C23 -> 140 | P23: =D23 -> 2 | Q23: =E23 -> 200 | R23: =F23 -> 6 | S23: 96.3 | T23: =H23 -> 413 | U23: =C23 -> 140 | V23: =J23 -> 2 | W23: =K23 -> 160 | X23: =L23 -> 6 | Y23: 135
A24: 5000 | B24: =(E24*D24)+(16.5*8)+(3*8)+(15*3) -> 721 | C24: ='Стандартные размеры KLM-S'!C26 -> 140 | D24: 4 | E24: ='Стандартные размеры KLM-S'!E26 -> 130 | F24: ='Стандартные размеры KLM-S'!F26 -> 6 | G24: 113.3 | H24: =(K24*J24)+(16.5*4)+(3*4)+15 -> 493 | I24: =C24 -> 140 | J24: 2 | K24: ='[1]Стандартные размеры'!K27 -> 200 | L24: =L23 -> 6 | M24: 185 | N24: =B24 -> 721 | O24: =C24 -> 140 | P24: =D24 -> 4 | Q24: =E24 -> 130 | R24: =F24 -> 6 | S24: 92.7 | T24: =H24 -> 493 | U24: =C24 -> 140 | V24: =J24 -> 2 | W24: =K24 -> 200 | X24: =L24 -> 6 | Y24: 220
A25: 6300 | B25: =(E25*D25)+(16.5*8)+(3*8)+(15*3) -> 841 | C25: ='Стандартные размеры KLM-S'!C27 -> 140 | D25: 4 | E25: ='Стандартные размеры KLM-S'!E27 -> 160 | F25: ='Стандартные размеры KLM-S'!F27 -> 6 | G25: 133.3 | H25: =(K25*J25)+(16.5*6)+(3*6)+(15*2) -> 747 | I25: =C25 -> 140 | J25: 3 | K25: ='[1]Стандартные размеры'!K28 -> 200 | L25: =L24 -> 6 | M25: 206.7 | N25: =B25 -> 841 | O25: =C25 -> 140 | P25: =D25 -> 4 | Q25: =E25 -> 160 | R25: =F25 -> 6 | S25: 142.7 | T25: =H25 -> 747 | U25: =C25 -> 140 | V25: =J25 -> 3 | W25: =K25 -> 200 | X25: =L25 -> 6 | Y25: 240
D27: Секция угловая горизонтальная CD
D28: Рекомендуемая кратность шага
D29: Шаг L1 = | G29: 50 мм.
D30: Шаг L2 = | G30: 50 мм.
A32: Номинальный ток | B32: 4р | H32: 5р
B33: алюминий | E33: медь | H33: алюминий | K33: медь
B34: L1, мм | C34: L2, мм | D34: Масса, кг | E34: L1, мм | F34: L2, мм | G34: Масса, кг | H34: L1, мм | I34: L2, мм | J34: Масса, кг | K34: L1, мм | L34: L2, мм | M34: Масса, кг
A35: 160
A36: 250
A37: 400
A38: 630 | B38: 435 | C38: 435 | E38: 435 | F38: 435 | H38: 435 | I38: 435 | K38: =E38 -> 435 | L38: =F38 -> 435
A39: 800 | B39: 435 | C39: =B39 -> 435 | E39: 435 | F39: =E39 -> 435 | H39: 435 | I39: 435 | K39: =E39 -> 435 | L39: =F39 -> 435
A40: 1000 | B40: 435 | C40: =B40 -> 435 | E40: 435 | F40: =E40 -> 435 | H40: 435 | I40: 435 | K40: =E40 -> 435 | L40: =F40 -> 435
A41: 1250 | B41: 435 | C41: =B41 -> 435 | E41: 435 | F41: =E41 -> 435 | H41: 435 | I41: 435 | K41: =E41 -> 435 | L41: =F41 -> 435
A42: 1600 | B42: 435 | C42: =B42 -> 435 | E42: 435 | F42: =E42 -> 435 | H42: 435 | I42: 435 | K42: =E42 -> 435 | L42: =F42 -> 435
A43: 2000 | B43: 435 | C43: =B43 -> 435 | E43: 435 | F43: =E43 -> 435 | H43: 435 | I43: 435 | K43: =E43 -> 435 | L43: =F43 -> 435
A44: 2500 | B44: 435 | C44: =B44 -> 435 | E44: 435 | F44: =E44 -> 435 | H44: 435 | I44: 435 | K44: =E44 -> 435 | L44: =F44 -> 435
...

Sheet Минимальные габариты IP55 и 68
A1: Приложение 9_Габаритные размеры шинопровода KLM-S, IP 55 с материалом корпуса V3, шиной толщиной 6мм
A3: Таблица размеров и масс
A5: Номинальный ток | B5: 4р | N5: 5р
B6: алюминий | H6: медь | N6: алюминий | T6: медь
B7: H, мм | C7: W, мм | D7: Шина | G7: Масса, кг пог/м | H7: H, мм | I7: W, мм | J7: Шина | M7: Масса, кг пог/м | N7: H, мм | O7: W, мм | P7: Шина | S7: Масса, кг пог/м | T7: H, мм | U7: W, мм | V7: Шина | Y7: Масса, кг пог/м
D8: Кол-во, шт | E8: Высота | F8: Толщина | J8: Кол-во, шт | K8: Высота | L8: Толщина | P8: Кол-во, шт | Q8: Высота | R8: Толщина | V8: Кол-во, шт | W8: Высота | X8: Толщина
A9: 160 | B9: 69 | C9: 140 | D9: 1 | E9: 30 | F9: 6 | H9: 69 | I9: 140 | J9: 1 | K9: 30 | L9: 6 | M9: 18.4 | N9: =B9 -> 69 | O9: =C9 -> 140 | P9: 1 | Q9: =E9 -> 30 | R9: =F9 -> 6 | S9: 6.7 | T9: =H9 -> 69 | U9: =C9 -> 140 | V9: 1 | W9: =K9 -> 30 | X9: =L9 -> 6 | Y9: 20.5
A10: 250 | B10: 69 | C10: 140 | D10: 1 | E10: 30 | F10: 6 | H10: 69 | I10: 140 | J10: 1 | K10: 30 | L10: 6 | M10: 18.4 | N10: =B10 -> 69 | O10: =C10 -> 140 | P10: 1 | Q10: =E10 -> 30 | R10: =F10 -> 6 | S10: 7.7 | T10: =H10 -> 69 | U10: =C10 -> 140 | V10: 1 | W10: =K10 -> 30 | X10: =L10 -> 6 | Y10: 20.5
A11: 315 | B11: 69 | C11: 140 | D11: 1 | E11: 30 | F11: 6 | H11: 69 | I11: 140 | J11: 1 | K11: 30 | L11: 6 | M11: 18.4 | N11: =B11 -> 69 | O11: =C11 -> 140 | P11: 1 | Q11: =E11 -> 30 | R11: =F11 -> 6 | S11: 8.7 | T11: =H11 -> 69 | U11: =C11 -> 140 | V11: 1 | W11: =K11 -> 30 | X11: =L11 -> 6 | Y11: 20.5
A12: 400 | B12: 69 | C12: 140 | D12: 1 | E12: 30 | F12: 6 | G12: 7.5 | H12: 69 | I12: 140 | J12: 1 | K12: 30 | L12: 6 | M12: 18.4 | N12: =B12 -> 69 | O12: =C12 -> 140 | P12: 1 | Q12: =E12 -> 30 | R12: =F12 -> 6 | S12: 8.7 | T12: =H12 -> 69 | U12: =C12 -> 140 | V12: 1 | W12: =K12 -> 30 | X12: =L12 -> 6 | Y12: 20.5
A13: 500 | B13: 69 | C13: 140 | D13: 1 | E13: 40 | F13: 6 | H13: 69 | I13: 140 | J13: 1 | K13: 30 | L13: 6 | M13: 18.4 | N13: =B13 -> 69 | O13: =C13 -> 140 | P13: 1 | Q13: =E13 -> 40 | R13: =F13 -> 6 | S13: 8.7 | T13: =H13 -> 69 | U13: =C13 -> 140 | V13: 1 | W13: =K13 -> 30 | X13: =L13 -> 6 | Y13: 20.5
A14: 630 | B14: 89 | C14: 140 | D14: 1 | E14: 50 | F14: 6 | G14: 9.4 | H14: 79 | I14: =C14 -> 140 | J14: 1 | K14: 40 | L14: 6 | M14: 20.6 | N14: =B14 -> 89 | O14: =C14 -> 140 | P14: 1 | Q14: =E14 -> 50 | R14: =F14 -> 6 | S14: 10.9 | T14: =H14 -> 79 | U14: =C14 -> 140 | V14: 1 | W14: =K14 -> 40 | X14: =L14 -> 6 | Y14: 23
A15: 800 | B15: 104 | C15: =C14 -> 140 | D15: 1 | E15: 65 | F15: 6 | G15: 10.7 | H15: 99 | I15: =C15 -> 140 | J15: 1 | K15: 60 | L15: =L14 -> 6 | M15: 20.6 | N15: =B15 -> 104 | O15: =C15 -> 140 | P15: 1 | Q15: =E15 -> 65 | R15: =F15 -> 6 | S15: 12.3 | T15: =H15 -> 99 | U15: =C15 -> 140 | V15: 1 | W15: =K15 -> 60 | X15: =L15 -> 6 | Y15: 23
A16: 1000 | B16: 139 | C16: =C15 -> 140 | D16: 1 | E16: 100 | F16: 6 | G16: 12.9 | H16: 104 | I16: =C16 -> 140 | J16: 1 | K16: 65 | L16: =L15 -> 6 | M16: 22.6 | N16: =B16 -> 139 | O16: =C16 -> 140 | P16: 1 | Q16: =E16 -> 100 | R16: =F16 -> 6 | S16: 13.7 | T16: =H16 -> 104 | U16: =C16 -> 140 | V16: 1 | W16: =K16 -> 65 | X16: =L16 -> 6 | Y16: 25.6
A17: 1250 | B17: 169 | C17: =C16 -> 140 | D17: 1 | E17: 130 | F17: 6 | G17: 15.9 | H17: 119 | I17: =C17 -> 140 | J17: 1 | K17: 80 | L17: =L16 -> 6 | M17: 25.6 | N17: =B17 -> 169 | O17: =C17 -> 140 | P17: 1 | Q17: =E17 -> 130 | R17: =F17 -> 6 | S17: 18.8 | T17: =H17 -> 119 | U17: =C17 -> 140 | V17: 1 | W17: =K17 -> 80 | X17: =L17 -> 6 | Y17: 28.6
A18: 1600 | B18: 199 | C18: =C17 -> 140 | D18: 1 | E18: 160 | F18: 6 | G18: 19.4 | H18: 139 | I18: =C18 -> 140 | J18: 1 | K18: 100 | L18: =L17 -> 6 | M18: 30.9 | N18: =B18 -> 199 | O18: =C18 -> 140 | P18: 1 | Q18: =E18 -> 160 | R18: =F18 -> 6 | S18: 23.1 | T18: =H18 -> 139 | U18: =C18 -> 140 | V18: 1 | W18: =K18 -> 100 | X18: =L18 -> 6 | Y18: 36.9
A19: 2000 | B19: 239 | C19: =C18 -> 140 | D19: 1 | E19: 200 | F19: 6 | G19: 23.3 | H19: 199 | I19: =C19 -> 140 | J19: 1 | K19: 160 | L19: =L18 -> 6 | M19: 38.8 | N19: =B19 -> 239 | O19: =C19 -> 140 | P19: 1 | Q19: =E19 -> 200 | R19: =F19 -> 6 | S19: 27.5 | T19: =H19 -> 199 | U19: =C19 -> 140 | V19: 1 | W19: =K19 -> 160 | X19: =L19 -> 6 | Y19: 46.8
A20: 2500 | B20: 348 | C20: =C19 -> 140 | D20: 2 | E20: 130 | F20: 6 | G20: 33.66 | H20: 239 | I20: =C20 -> 140 | J20: 1 | K20: 200 | L20: =L19 -> 6 | M20: 46.6 | N20: =B20 -> 348 | O20: =C20 -> 140 | P20: =D20 -> 2 | Q20: =E20 -> 130 | R20: =F20 -> 6 | S20: 39.3 | T20: =H20 -> 239 | U20: =C20 -> 140 | V20: 1 | W20: =K20 -> 200 | X20: =L20 -> 6 | Y20: 49.8
A21: 3200 | B21: 408 | C21: =C20 -> 140 | D21: 2 | E21: 160 | F21: 6 | G21: 39.5 | H21: 348 | I21: =C21 -> 140 | J21: 2 | K21: 130 | L21: =L20 -> 6 | M21: 62.6 | N21: =B21 -> 408 | O21: =C21 -> 140 | P21: =D21 -> 2 | Q21: =E21 -> 160 | R21: =F21 -> 6 | S21: 46.3 | T21: =H21 -> 348 | U21: =C21 -> 140 | V21: =J21 -> 2 | W21: =K21 -> 130 | X21: =L21 -> 6 | Y21: 74.8
A22: 4000 | B22: 488 | C22: =C21 -> 140 | D22: 2 | E22: 200 | F22: 6 | G22: 47.5 | H22: 408 | I22: =C22 -> 140 | J22: 2 | K22: 160 | L22: =L21 -> 6 | M22: 93.9 | N22: =B22 -> 488 | O22: =C22 -> 140 | P22: =D22 -> 2 | Q22: =E22 -> 200 | R22: =F22 -> 6 | S22: 55.3 | T22: =H22 -> 408 | U22: =C22 -> 140 | V22: =J22 -> 2 | W22: =K22 -> 160 | X22: =L22 -> 6 | Y22: 114.7
A23: 5000 | B23: 706 | C23: =C22 -> 140 | D23: 4 | E23: 130 | F23: 6 | G23: 67.4 | H23: 488 | I23: =C23 -> 140 | J23: 2 | K23: 200 | L23: =L22 -> 6 | M23: 124.6 | N23: =B23 -> 706 | O23: =C23 -> 140 | P23: =D23 -> 4 | Q23: =E23 -> 130 | R23: =F23 -> 6 | S23: 77.3 | T23: =H23 -> 488 | U23: =C23 -> 140 | V23: =J23 -> 2 | W23: =K23 -> 200 | X23: =L23 -> 6 | Y23: 152.6
A24: 6300 | B24: 826 | C24: =C23 -> 140 | D24: 4 | E24: 160 | F24: 6 | G24: 74.7 | H24: 737 | I24: =C24 -> 140 | J24: 3 | K24: 200 | L24: =L23 -> 6 | M24: 156.1 | N24: =B24 -> 826 | O24: =C24 -> 140 | P24: =D24 -> 4 | Q24: =E24 -> 160 | R24: =F24 -> 6 | S24: 90.7 | T24: =H24 -> 737 | U24: =C24 -> 140 | V24: =J24 -> 3 | W24: =K24 -> 200 | X24: =L24 -> 6 | Y24: 168.1
A25: *Pi (окна только на одной стороне секции) | B25: до 2000мм без окон окона отбора мощности
B26: от 2000-3000мм 1 оконо отбора мощности
B27: 3000мм 2 окона отбора мощности | AA27: \\\ТР | AB27: =(E23*D23)+(40*3)+(3*6)+(3*4)+(18*2) -> 706
A32: Секция прямая FE | B32: Минимальная длина прямой секции | G32: =(11+93+90)*2+2 -> 390 | H32: мм
A34: Секция угловая горизонтальная CD
A36: Номинальный ток | B36: 4р | L36: 5р
B37: алюминий | G37: медь | L37: алюминий | Q37: медь
B38: L1, мм | C38: l1, мм | D38: L2, мм | E38: l2, мм | G38: L1, мм | H38: l1, мм | I38: L2, мм | J38: l2, мм | L38: L1, мм | M38: l1, мм | N38: L2, мм | O38: l2, мм | Q38: L1, мм | R38: l1, мм | S38: L2, мм | T38: l2, мм
A39: =A9 -> 160 | B39: =11+93+90+C9 -> 334 | C39: =B39-(C9/2) -> 264 | D39: =B39 -> 334 | E39: =C39 -> 264 | G39: =11+93+90+I9 -> 334 | H39: =G39-(I9/2) -> 264 | I39: =G39 -> 334 | J39: =H39 -> 264 | L39: =B39 -> 334 | M39: =C39 -> 264 | N39: =L39 -> 334 | O39: =M39 -> 264 | Q39: =G39 -> 334 | R39: =H39 -> 264 | S39: =Q39 -> 334 | T39: =R39 -> 264
A40: =A10 -> 250 | B40: =11+93+90+I9 -> 334 | C40: =B40-(C9/2) -> 264 | D40: =B40 -> 334 | E40: =C40 -> 264 | G40: =11+93+90+I10 -> 334 | H40: =G40-(I9/2) -> 264 | I40: =G40 -> 334 | J40: =H40 -> 264 | L40: =B40 -> 334 | M40: =C40 -> 264 | N40: =L40 -> 334 | O40: =M40 -> 264 | Q40: =G40 -> 334 | R40: =H40 -> 264 | S40: =Q40 -> 334 | T40: =R40 -> 264
A41: =A11 -> 315 | B41: =11+93+90+I10 -> 334 | C41: =B41-(C10/2) -> 264 | D41: =B41 -> 334 | E41: =C41 -> 264 | G41: =11+93+90+I11 -> 334 | H41: =G41-(I10/2) -> 264 | I41: =G41 -> 334 | J41: =H41 -> 264 | L41: =B41 -> 334 | M41: =C41 -> 264 | N41: =L41 -> 334 | O41: =M41 -> 264 | Q41: =G41 -> 334 | R41: =H41 -> 264 | S41: =Q41 -> 334 | T41: =R41 -> 264
A42: =A12 -> 400 | B42: =11+93+90+I11 -> 334 | C42: =B42-(C11/2) -> 264 | D42: =B42 -> 334 | E42: =C42 -> 264 | G42: =11+93+90+I12 -> 334 | H42: =G42-(I11/2) -> 264 | I42: =G42 -> 334 | J42: =H42 -> 264 | L42: =B42 -> 334 | M42: =C42 -> 264 | N42: =L42 -> 334 | O42: =M42 -> 264 | Q42: =G42 -> 334 | R42: =H42 -> 264 | S42: =Q42 -> 334 | T42: =R42 -> 264
A43: =A13 -> 500 | B43: =11+93+90+I12 -> 334 | C43: =B43-(C12/2) -> 264 | D43: =B43 -> 334 | E43: =C43 -> 264 | G43: =11+93+90+I13 -> 334 | H43: =G43-(I12/2) -> 264 | I43: =G43 -> 334 | J43: =H43 -> 264 | L43: =B43 -> 334 | M43: =C43 -> 264 | N43: =L43 -> 334 | O43: =M43 -> 264 | Q43: =G43 -> 334 | R43: =H43 -> 264 | S43: =Q43 -> 334 | T43: =R43 -> 264
A44: =A14 -> 630 | B44: =11+93+90+I13 -> 334 | C44: =B44-(C13/2) -> 264 | D44: =B44 -> 334 | E44: =C44 -> 264 | G44: =11+93+90+I14 -> 334 | H44: =G44-(I13/2) -> 264 | I44: =G44 -> 334 | J44: =H44 -> 264 | L44: =B44 -> 334 | M44: =C44 -> 264 | N44: =L44 -> 334 | O44: =M44 -> 264 | Q44: =G44 -> 334 | R44: =H44 -> 264 | S44: =Q44 -> 334 | T44: =R44 -> 264
A45: =A15 -> 800 | B45: =11+93+90+I14 -> 334 | C45: =B45-(C14/2) -> 264 | D45: =B45 -> 334 | E45: =C45 -> 264 | G45: =11+93+90+I15 -> 334 | H45: =G45-(I14/2) -> 264 | I45: =G45 -> 334 | J45: =H45 -> 264 | L45: =B45 -> 334 | M45: =C45 -> 264 | N45: =L45 -> 334 | O45: =M45 -> 264 | Q45: =G45 -> 334 | R45: =H45 -> 264 | S45: =Q45 -> 334 | T45: =R45 -> 264
A46: =A16 -> 1000 | B46: =11+93+90+I15 -> 334 | C46: =B46-(C15/2) -> 264 | D46: =B46 -> 334 | E46: =C46 -> 264 | G46: =11+93+90+I16 -> 334 | H46: =G46-(I15/2) -> 264 | I46: =G46 -> 334 | J46: =H46 -> 264 | L46: =B46 -> 334 | M46: =C46 -> 264 | N46: =L46 -> 334 | O46: =M46 -> 264 | Q46: =G46 -> 334 | R46: =H46 -> 264 | S46: =Q46 -> 334 | T46: =R46 -> 264
A47: =A17 -> 1250 | B47: =11+93+90+I16 -> 334 | C47: =B47-(C16/2) -> 264 | D47: =B47 -> 334 | E47: =C47 -> 264 | G47: =11+93+90+I17 -> 334 | H47: =G47-(I16/2) -> 264 | I47: =G47 -> 334 | J47: =H47 -> 264 | L47: =B47 -> 334 | M47: =C47 -> 264 | N47: =L47 -> 334 | O47: =M47 -> 264 | Q47: =G47 -> 334 | R47: =H47 -> 264 | S47: =Q47 -> 334 | T47: =R47 -> 264
A48: =A18 -> 1600 | B48: =11+93+90+I17 -> 334 | C48: =B48-(C17/2) -> 264 | D48: =B48 -> 334 | E48: =C48 -> 264 | G48: =11+93+90+I18 -> 334 | H48: =G48-(I17/2) -> 264 | I48: =G48 -> 334 | J48: =H48 -> 264 | L48: =B48 -> 334 | M48: =C48 -> 264 | N48: =L48 -> 334 | O48: =M48 -> 264 | Q48: =G48 -> 334 | R48: =H48 -> 264 | S48: =Q48 -> 334 | T48: =R48 -> 264
...

Sheet История изменений
B2: Версия | C2: Дата | D2: Что изменилось
B3: 1.8 | C3: 46146 | D3: В минимальных размерах L1 для элемента ZP номинал от 1000А до 2500А приведены в соответствие CP угла.
B4: 1.9 | C4: 21.05.2026 | D4: В минимальных размерах L1 и L2 для элемента TP увеличился размер в большую сторону. Не учтены была крышка.

Sheet Максимальные размеры  IP55
A1: Максимальные размеры элементов шинопровода KLM-S, IP55 конструктива 13/V3
D3: Таблица размеров и масс
D4: Секция угловая горизонтальная FE
D5: Рекомендуемая кратность шага
D6: Шаг L1 = | G6: 10 мм.
A8: Номинальный ток | B8: 4р | N8: 5р
B9: алюминий | H9: медь | N9: алюминий | T9: медь
B10: H, мм | C10: W, мм | D10: Шина | G10: Масса, кг пог/м | H10: H, мм | I10: W, мм | J10: Шина | M10: Масса, кг пог/м | N10: H, мм | O10: W, мм | P10: Шина | S10: Масса, кг пог/м | T10: H, мм | U10: W, мм | V10: Шина | Y10: Масса, кг пог/м
D11: Кол-во, шт | E11: Высота | F11: Толщина | J11: Кол-во, шт | K11: Высота | L11: Толщина | P11: Кол-во, шт | Q11: Высота | R11: Толщина | V11: Кол-во, шт | W11: Высота | X11: Толщина
A12: 160 | B12: =E12+18+18+3 -> 69 | C12: 140 | D12: 1 | E12: 30 | F12: 6 | G12: 7.5 | H12: =K12+18+18+3 -> 69 | I12: 140 | J12: 1 | K12: 30 | L12: 6 | M12: 18.4 | N12: =B12 -> 69 | O12: =C12 -> 140 | P12: =D12 -> 1 | Q12: =E12 -> 30 | R12: =F12 -> 6 | S12: 6.7 | T12: =H12 -> 69 | U12: =C12 -> 140 | V12: =J12 -> 1 | W12: =K12 -> 30 | X12: =L12 -> 6 | Y12: 18.5
A13: 250 | B13: =E13+18+18+3 -> 69 | C13: 140 | D13: 1 | E13: 30 | F13: 6 | G13: 7.5 | H13: =K13+18+18+3 -> 69 | I13: 140 | J13: 1 | K13: 30 | L13: 6 | M13: 18.4 | N13: =B13 -> 69 | O13: =C13 -> 140 | P13: =D13 -> 1 | Q13: =E13 -> 30 | R13: =F13 -> 6 | S13: 7.7 | T13: =H13 -> 69 | U13: =C13 -> 140 | V13: =J13 -> 1 | W13: =K13 -> 30 | X13: =L13 -> 6 | Y13: 19.5
A14: 400 | B14: =E14+18+18+3 -> 69 | C14: 140 | D14: 1 | E14: 30 | F14: 6 | G14: 7.5 | H14: =K14+18+18+3 -> 69 | I14: 140 | J14: 1 | K14: 30 | L14: 6 | M14: 18.4 | N14: =B14 -> 69 | O14: =C14 -> 140 | P14: =D14 -> 1 | Q14: =E14 -> 30 | R14: =F14 -> 6 | S14: 8.7 | T14: =H14 -> 69 | U14: =C14 -> 140 | V14: =J14 -> 1 | W14: =K14 -> 30 | X14: =L14 -> 6 | Y14: 20.5
A15: 630 | B15: =E15+18+18+3 -> 89 | C15: 140 | D15: 1 | E15: 50 | F15: 6 | G15: 9.4 | H15: =K15+18+18+3 -> 79 | I15: =C15 -> 140 | J15: 1 | K15: 40 | L15: 6 | M15: 20.6 | N15: =B15 -> 89 | O15: =C15 -> 140 | P15: =D15 -> 1 | Q15: =E15 -> 50 | R15: =F15 -> 6 | S15: 10.9 | T15: =H15 -> 79 | U15: =C15 -> 140 | V15: =J15 -> 1 | W15: =K15 -> 40 | X15: =L15 -> 6 | Y15: 23
A16: 800 | B16: =E16+18+18+3 -> 104 | C16: =C15 -> 140 | D16: 1 | E16: 65 | F16: 6 | G16: 10.7 | H16: =K16+18+18+3 -> 99 | I16: =C16 -> 140 | J16: 1 | K16: 60 | L16: =L15 -> 6 | M16: 20.6 | N16: =B16 -> 104 | O16: =C16 -> 140 | P16: =D16 -> 1 | Q16: =E16 -> 65 | R16: =F16 -> 6 | S16: 12.3 | T16: =H16 -> 99 | U16: =C16 -> 140 | V16: =J16 -> 1 | W16: =K16 -> 60 | X16: =L16 -> 6 | Y16: 23
A17: 1000 | B17: =E17+18+18+3 -> 139 | C17: =C16 -> 140 | D17: 1 | E17: 100 | F17: 6 | G17: 12.9 | H17: =K17+18+18+3 -> 104 | I17: =C17 -> 140 | J17: 1 | K17: 65 | L17: =L16 -> 6 | M17: 22.6 | N17: =B17 -> 139 | O17: =C17 -> 140 | P17: =D17 -> 1 | Q17: =E17 -> 100 | R17: =F17 -> 6 | S17: 13.7 | T17: =H17 -> 104 | U17: =C17 -> 140 | V17: =J17 -> 1 | W17: =K17 -> 65 | X17: =L17 -> 6 | Y17: 25.6
A18: 1250 | B18: =E18+18+18+3 -> 169 | C18: =C17 -> 140 | D18: 1 | E18: 130 | F18: 6 | G18: 15.9 | H18: =K18+18+18+3 -> 119 | I18: =C18 -> 140 | J18: 1 | K18: 80 | L18: =L17 -> 6 | M18: 25.6 | N18: =B18 -> 169 | O18: =C18 -> 140 | P18: =D18 -> 1 | Q18: =E18 -> 130 | R18: =F18 -> 6 | S18: 18.8 | T18: =H18 -> 119 | U18: =C18 -> 140 | V18: 1 | W18: =K18 -> 80 | X18: =L18 -> 6 | Y18: 28.6
A19: 1600 | B19: =E19+18+18+3 -> 199 | C19: =C18 -> 140 | D19: 1 | E19: 160 | F19: 6 | G19: 19.4 | H19: =K19+18+18+3 -> 139 | I19: =C19 -> 140 | J19: 1 | K19: 100 | L19: =L18 -> 6 | M19: 30.9 | N19: =B19 -> 199 | O19: =C19 -> 140 | P19: =D19 -> 1 | Q19: =E19 -> 160 | R19: =F19 -> 6 | S19: 23.1 | T19: =H19 -> 139 | U19: =C19 -> 140 | V19: 1 | W19: =K19 -> 100 | X19: =L19 -> 6 | Y19: 36.9
A20: 2000 | B20: =E20+18+18+3 -> 239 | C20: =C19 -> 140 | D20: 1 | E20: 200 | F20: 6 | G20: 23.3 | H20: =K20+18+18+3 -> 199 | I20: =C20 -> 140 | J20: 1 | K20: 160 | L20: =L19 -> 6 | M20: 38.8 | N20: =B20 -> 239 | O20: =C20 -> 140 | P20: =D20 -> 1 | Q20: =E20 -> 200 | R20: =F20 -> 6 | S20: 27.5 | T20: =H20 -> 199 | U20: =C20 -> 140 | V20: 1 | W20: =K20 -> 160 | X20: =L20 -> 6 | Y20: 46.8
A21: 2500 | B21: =(E21*D21)+18+18+(3*D21)+(3*D21)+40 -> 348 | C21: =C20 -> 140 | D21: 2 | E21: 130 | F21: 6 | G21: 33.66 | H21: =K21+18+18+3 -> 239 | I21: =C21 -> 140 | J21: 1 | K21: 200 | L21: =L20 -> 6 | M21: 46.6 | N21: =B21 -> 348 | O21: =C21 -> 140 | P21: =D21 -> 2 | Q21: =E21 -> 130 | R21: =F21 -> 6 | S21: 39.3 | T21: =H21 -> 239 | U21: =C21 -> 140 | V21: 1 | W21: =K21 -> 200 | X21: =L21 -> 6 | Y21: 49.8
A22: 3200 | B22: =(E22*D22)+18+18+(3*D22)+(3*D22)+40 -> 408 | C22: =C21 -> 140 | D22: 2 | E22: 160 | F22: 6 | G22: 39.5 | H22: =(K22*J22)+18+18+(3*J22)+(3*J22)+40 -> 348 | I22: =C22 -> 140 | J22: 2 | K22: 130 | L22: =L21 -> 6 | M22: 62.6 | N22: =B22 -> 408 | O22: =C22 -> 140 | P22: =D22 -> 2 | Q22: =E22 -> 160 | R22: =F22 -> 6 | S22: 46.3 | T22: =H22 -> 348 | U22: =C22 -> 140 | V22: =J22 -> 2 | W22: =K22 -> 130 | X22: =L22 -> 6 | Y22: 74.8
A23: 4000 | B23: =(E23*D23)+18+18+(3*D23)+(3*D23)+40 -> 488 | C23: =C22 -> 140 | D23: 2 | E23: 200 | F23: 6 | G23: 47.5 | H23: =(K23*J23)+18+18+(3*J23)+(3*J23)+40 -> 408 | I23: =C23 -> 140 | J23: 2 | K23: 160 | L23: =L22 -> 6 | M23: 93.9 | N23: =B23 -> 488 | O23: =C23 -> 140 | P23: =D23 -> 2 | Q23: =E23 -> 200 | R23: =F23 -> 6 | S23: 55.3 | T23: =H23 -> 408 | U23: =C23 -> 140 | V23: =J23 -> 2 | W23: =K23 -> 160 | X23: =L23 -> 6 | Y23: 114.7
A24: 5000 | B24: =(E24*D24)+18+18+(3*6)+(3*D24)+(40*3) -> 706 | C24: =C23 -> 140 | D24: 4 | E24: 130 | F24: 6 | G24: 67.4 | H24: =(K24*J24)+18+18+(3*J24)+(3*J24)+40 -> 488 | I24: =C24 -> 140 | J24: 2 | K24: 200 | L24: =L23 -> 6 | M24: 124.6 | N24: =B24 -> 706 | O24: =C24 -> 140 | P24: =D24 -> 4 | Q24: =E24 -> 130 | R24: =F24 -> 6 | S24: 77.3 | T24: =H24 -> 488 | U24: =C24 -> 140 | V24: =J24 -> 2 | W24: =K24 -> 200 | X24: =L24 -> 6 | Y24: 152.6
A25: 6300 | B25: =(E25*D25)+18+18+(3*6)+(3*D25)+(40*3) -> 826 | C25: =C24 -> 140 | D25: 4 | E25: 160 | F25: 6 | G25: 74.7 | H25: =(K25*J25)+18+18+(3*4)+(3*J25)+40*2 -> 737 | I25: =C25 -> 140 | J25: 3 | K25: 200 | L25: =L24 -> 6 | M25: 156.1 | N25: =B25 -> 826 | O25: =C25 -> 140 | P25: =D25 -> 4 | Q25: =E25 -> 160 | R25: =F25 -> 6 | S25: 90.7 | T25: =H25 -> 737 | U25: =C25 -> 140 | V25: =J25 -> 3 | W25: =K25 -> 200 | X25: =L25 -> 6 | Y25: 168.1
A26: *Pi (окна только на одной стороне секции) | B26: до 1000мм без окон окона отбора мощности
B27: от 1000-2000мм 1 оконо отбора мощности
B28: 3000мм 2 окона отбора мощности
A31: Номинальный ток | B31: 4р | H31: 5р
B32: алюминий | E32: медь | H32: алюминий | K32: медь
B33: H, мм | C33: W, мм | D33: Масса, кг/м | E33: H, мм | F33: W, мм | G33: Масса, кг/м | H33: H, мм | I33: W, мм | J33: Масса, кг/м | K33: H, мм | L33: W, мм | M33: Масса, кг/м
A34: 400 | C34: 140
A35: 630 | C35: 140
A36: 800 | B36: 114 | C36: 140 | D36: 10.8 | E36: 104 | F36: 140 | G36: 20.666667 | H36: 114 | I36: 140 | J36: 12.333333 | K36: 104 | L36: 140 | M36: 23
A37: 1000 | B37: 139 | C37: 140 | D37: 13.5 | E37: 104 | F37: 140 | G37: 22.666667 | H37: 139 | I37: 140 | J37: 15.433333 | K37: 104 | L37: 140 | M37: 25.666667
A38: 1250 | B38: 169 | C38: 140 | D38: 16.333333 | E38: 114 | F38: 140 | G38: 25.666667 | H38: 169 | I38: 140 | J38: 18.8 | K38: 114 | L38: 140 | M38: 28.666667
A39: 1600 | B39: 199 | C39: 140 | D39: 20.333333 | E39: 139 | F39: 140 | G39: 30.766667 | H39: 199 | I39: 140 | J39: 23.066667 | K39: 139 | L39: 140 | M39: 36.9
A40: 2000 | B40: 239 | C40: 140 | D40: 23.333333 | E40: 169 | F40: 140 | G40: 38.833333 | H40: 239 | I40: 140 | J40: 27.766667 | K40: 169 | L40: 140 | M40: 46.833333
A41: 2500 | B41: 349 | C41: 140 | D41: 33.6 | E41: 199 | F41: 140 | G41: 46.666667 | H41: 349 | I41: 140 | J41: 39.333333 | K41: 199 | L41: 140 | M41: 49.833333
A42: 3200 | B42: 409 | C42: 140 | D42: 39.266667 | E42: 289 | F42: 140 | G42: 62.633333 | H42: 409 | I42: 140 | J42: 46.333333 | K42: 289 | L42: 140 | M42: 74.833333
A43: 4000 | B43: 489 | C43: 140 | D43: 46.866667 | E43: 409 | F43: 140 | G43: 93.933333 | H43: 489 | I43: 140 | J43: 55.266667 | K43: 409 | L43: 140 | M43: 114.76667
A44: 5000 | B44: 709 | C44: 140 | D44: 67.433333 | E44: 619 | F44: 140 | G44: 124.66667 | H44: 709 | I44: 140 | J44: 77.333333 | K44: 619 | L44: 140 | M44: 152.66667
...
